Workbook

Sheet P0 Project overview
B2: P0. Project overview
B4: 1. Purpose
B5: This workbook | C5: Single working file for SR26 data collection and project delivery: requirements, requests, responses, scoring, evidence, plus project plan, timeline, comms/web to-do list and content-contributor checklist (P-tabs).
B6: SR26 in one line | C6: Transition-year report covering CY2026: distinguish activity under the former Sustainability Plan 2030 from foundations and early actions after the Sustainability 2030 launch (~20 Oct 2026 TBC). No published traffic lights in 2026.
B8: 2. Lessons from SR25 and actions for SR26
B9: Keep tailored data requests | C9: SR25 streamlined requests achieved a 100% response rate → keep targeted, faculty-specific requests (see Request wording log); avoid complex requests.
B10: Keep independent senior review | C10: Retain Target Status Review Group as the Sustainability Reporting Review Group (~15 Feb 2027).
B11: Strengthen data controls | C11: Central Evidence register, data owner confirmation (columns Q–R on every request), data source records, Databook alignment.
B12: Integrate with Annual Report | C12: Engage Annual Report team in October; shared dependency map; late operational data (Feb–Mar) on a later pathway.
B13: Agree comms roles early | C13: RASCI with Strategic Communications, comms, digital and design at project start (P2.3 RASCI matrix).
B14: Plan web and close from the outset | C14: Year-specific report URL, central landing page, analytics measures agreed before launch, formal retrospective (P3, P2).
B15: Simpler project management | C15: This simplified tracker; induction walkthrough; direct messages for assigned tasks, group channel for shared updates; blocker escalation as a standing meeting item.
B16: Follow up non-approval | C16: SR25: FBE filled in the template but did not approve; Science disagreed with metrics → track 'Owner confirmed' in the Request tracker and chase; offer January support meetings.
B18: 3. How to use this workbook
B19: Records management | C19: Save on the Sustainability Strategy Team SharePoint (Sustainability report 2026 > Report development). One document owner per working file; notify collaborators when a new version is saved. Avoid extra sub-folders in the data folder.
B20: Responses | C20: Paste returned responses into the Faculties / central-unit tabs without inserting rows inside a block (A1/0.5/T2 formulas look up by Ref).
B21: Regenerating | C21: Templates are generated by build.py – update settings there to add faculties/units, then re-run.
B23: 4. Key reference documents
B24: SR26 approach | C24: 2026 Sustainability reporting approach & target status assessment framework – DRAFT Sep 2026
B25: SR25 documents | C25: SR25 Reporting framework (Jan 2026); Faculty/portfolio engagement plan and comms 2025-26; 2025 end-year reporting master spreadsheet V0.2; Target status review process doc (Jan 2026); Target status assessment (final 18.3.26); SR25 Final (Word); SR25 Project close report and key lessons learnt
B26: Targets | C26: Sustainability 2030 Updated Targets (Not for distribution) – Qual and Quan worksheets
B28: 5. Team processes
B29: Meetings | C29: Weekly production meeting (SST + comms/design); standing items: progress, blockers/escalation, decisions.
B30: Communication | C30: Direct messages for individual tasks; group channel for shared updates.

Sheet P1 Project plan
B2: P1. SR26 Project plan on a page
B4: Project plan on a page
B5: Version control | C5: DRAFT v0.27 – based on SR26 approach (Sep 2026)
B6: Context | C6: The annual Sustainability Report is the University's core public account of sustainability progress. SR26 is a transition report following the refreshed Sustainability 2030 launch (~20 Oct 2026).
B7: Objectives / principles | C7: Accurate and transparent (clear transition-year framing) • Fit-for-purpose (request only what is necessary, available and usable) • Evidence-led (each request linked to an indicator, report use and evidence) • Integrated (Databook is the primary quantitative source) • Reusable (templates and roles for 2027+) • Accessible (one web page per priority area: narrative + case studies) • Credible (independent review; traffic-light ratings deferred to 2027 reporting)
B8: Reporting model | C8: Webpages by priority area; transition-year framing; no published traffic lights (internal ratings only); Databook for quantitative data; targeted qualitative requests; early case-study pipeline; Sustainability Reporting Review Group.
B9: Workstreams | C9: Governance • Data collection & analysis (this workbook) • Content development • Communications & web build
B10: Key stakeholders | C10: Director, Sustainability (decision owner) • COO • VCAG • University Executive • University Council • Investment Management Committee • Sustainability Reporting Review Group • Associate Deans Sustainability • Priority-area working groups • Central data owners (CI&S, CFOG, ESG, CIOG, MRE, AC&M, GCE, Education, SaSS, Indigenous, L&R) • Strategic Communications, digital & design • University Annual Report team
B11: Phases | C11: Sep–Oct 2026 Set-up • Oct 2026 Process design & launch • Nov–Dec 2026 Evidence collection • Jan 2027 Drafting & validation • Feb–May 2027 Review & governance • May–Jun 2027 Publication & close-out
B12: Outputs | C12: Requirements matrix • Request templates • Evidence register • Case-study pipeline • Draft report & issues paper • VCAG/UE/Council papers • Report website • Retrospective
B13: Success measures | C13: Response rate • Reporting burden • Project effort • Data-quality issues • Web sessions, users and views • Stakeholder feedback
B15: Key risks and controls
B16: Full-year implication | C16: Report implies a full year of progress against targets launched 20 Oct → explicit transition-year framing.
B17: Onerous requests | C17: Requests onerous or non-comparable → necessity and usability test; pilot templates; don't ask for data areas can't hold.
B18: Databook overlap | C18: Databook and narrative requests overlap/conflict → one requirements matrix and evidence register; one source of truth per indicator.
B19: New working groups | C19: Asked to evidence delivery before established → maturity-based 2026 request.
B20: Case studies dominate | C20: → selection criteria: relevance, evidence, outcome, transferability, balance, permission.
B21: Late responses | C21: → issue requirements early, support meetings, senior sponsorship, escalate gaps.
B22: Review group role | C22: Unclear without traffic lights → approve review criteria and decision rights in advance.
B23: Annual Report divergence | C23: → engage in October; shared dependency/data map; reconcile shared figures.
B25: Decisions required (from SR26 approach)
B26: 1. Transition-year model | C26: Director, Sustainability – Approved (internal traffic lights: sub-decision)
B27: 2. Evidence & engagement model | C27: Director, Sustainability – Pending (awaiting Stefanus' WIP)
B28: 3. Assurance & governance pathway | C28: Director, Sustainability – Closed
B29: 4. Modern slavery timeline alignment | C29: Director, Sustainability (and Head of Procurement) – Open, watch item

Sheet P2.1 Governance deadlines
B2: P2.1 Governance paper deadlines
B3: Placeholders – confirm with governance offices. Type the Meeting and Papers due dates; the grey columns and the P2.2 Timeline update automatically. Leader review = papers due – 3 working days (weekends skipped, not public holidays).
B5: Governance body | C5: Purpose | D5: Meeting | E5: Papers due | F5: To leaders for review (papers – 3 working days) | G5: Begin drafting (proposed: papers – 10 working days) | H5: Source of placeholder
B6: Sustainability Reporting Review Group | C6: Review findings | D6: 46433 | E6: 46426 | F6: =WORKDAY(E6,-3) | G6: =WORKDAY(E6,-10) | H6: SR26 approach (~15 Feb); SR25 n/a
B7: VCAG | C7: Notes Review Group findings | D7: 46434 | E7: 46428 | F7: =WORKDAY(E7,-3) | G7: =WORKDAY(E7,-10) | H7: SR26 approach; SR25: papers 14 Feb, meeting 17 Feb
B8: Investment Management Committee | C8: Responsible investments section | D8: 46443 | E8: 46436 | F8: =WORKDAY(E8,-3) | G8: =WORKDAY(E8,-10) | H8: SR26 approach (TBC)
B9: VCAG | C9: Notes full report | D9: 46448 | E9: 46443 | F9: =WORKDAY(E9,-3) | G9: =WORKDAY(E9,-10) | H9: SR26 approach (TBC)
B10: University Executive | C10: Notes report | D10: 46471 | E10: 46458 | F10: =WORKDAY(E10,-3) | G10: =WORKDAY(E10,-10) | H10: SR26 approach; SR25: papers 17 Mar, meeting 27 Mar
B11: University Council | C11: Approves report | D11: 46513 | E11: 46486 | F11: =WORKDAY(E11,-3) | G11: =WORKDAY(E11,-10) | H11: SR26 approach (~10 Apr); SR25: meeting 5 May

Sheet P2.2 Timeline
B2: P2.2 Timeline
B3: Bars fill from Start/End; ◆ = milestone; green = Complete; grey = Christmas shutdown; light blue = governance papers due (dates from P2.1 Governance deadlines); red header = this week. Lead (R) and Accountable (A) come from P2.3 RASCI matrix.
L5: =TRIM(IF(AND('P2.1 Governance deadlines'!$E$6>=L$7,'P2.1 Governance deadlines'!$E$6<=L$7+6),"Review Grp papers ","")&IF(AND('P2.1 Governance deadlines'!$D$6>=L$7,'P2.1 Governance deadlines'!$D$6<=L$7+6),"Review Grp meet ","")&IF(AND('P2.1 Governance deadlines'!$E$7>=L$7,'P2.1 Governance deadlines'!$E$7<=L$7+6),"VCAG papers ","")&IF(AND('P2.1 Governance deadlines'!$D$7>=L$7,'P2.1 Governance deadlines'!$D$7<=L$7+6),"VCAG meet ","")&IF(AND('P2.1 Governance deadlines'!$E$8>=L$7,'P2.1 Governance deadlines'!$E$8<=L$7+6),"IMC papers ","")&IF(AND('P2.1 Governance deadlines'!$D$8>=L$7,'P2.1 Governance deadlines'!$D$8<=L$7+6),"IMC meet ","")&IF(AND('P2.1 Governance deadlines'!$E$9>=L$7,'P2.1 Governance deadlines'!$E$9<=L$7+6),"VCAG papers ","")&IF(AND('P2.1 Governance deadlines'!$D$9>=L$7,'P2.1 Governance deadlines'!$D$9<=L$7+6),"VCAG meet ","")&IF(AND('P2.1 Governance deadlines'!$E$10>=L$7,'P2.1 Governance deadlines'!$E$10<=L$7+6),"UE papers ","")&IF(AND('P2.1 Governance deadlines'!$D$10>=L$7,'P2.1 Governance deadlines'!$D$10<=L$7+6),"UE meet ","")&IF(AND('P2.1 Governance deadlines'!$E$11>=L$7,'P2.1 Governance deadlines'!$E$11<=L$7+6),"UC papers ","")&IF(AND('P2.1 Governance deadlines'!$D$11>=L$7,'P2.1 Governance deadlines'!$D$11<=L$7+6),"UC meet ","")) | M5: =TRIM(IF(AND('P2.1 Governance deadlines'!$E$6>=M$7,'P2.1 Governance deadlines'!$E$6<=M$7+6),"Review Grp papers ","")&IF(AND('P2.1 Governance deadlines'!$D$6>=M$7,'P2.1 Governance deadlines'!$D$6<=M$7+6),"Review Grp meet ","")&IF(AND('P2.1 Governance deadlines'!$E$7>=M$7,'P2.1 Governance deadlines'!$E$7<=M$7+6),"VCAG papers ","")&IF(AND('P2.1 Governance deadlines'!$D$7>=M$7,'P2.1 Governance deadlines'!$D$7<=M$7+6),"VCAG meet ","")&IF(AND('P2.1 Governance deadlines'!$E$8>=M$7,'P2.1 Governance deadlines'!$E$8<=M$7+6),"IMC papers ","")&IF(AND('P2.1 Governance deadlines'!$D$8>=M$7,'P2.1 Governance deadlines'!$D$8<=M$7+6),"IMC meet ","")&IF(AND('P2.1 Governance deadlines'!$E$9>=M$7,'P2.1 Governance deadlines'!$E$9<=M$7+6),"VCAG papers ","")&IF(AND('P2.1 Governance deadlines'!$D$9>=M$7,'P2.1 Governance deadlines'!$D$9<=M$7+6),"VCAG meet ","")&IF(AND('P2.1 Governance deadlines'!$E$10>=M$7,'P2.1 Governance deadlines'!$E$10<=M$7+6),"UE papers ","")&IF(AND('P2.1 Governance deadlines'!$D$10>=M$7,'P2.1 Governance deadlines'!$D$10<=M$7+6),"UE meet ","")&IF(AND('P2.1 Governance deadlines'!$E$11>=M$7,'P2.1 Governance deadlines'!$E$11<=M$7+6),"UC papers ","")&IF(AND('P2.1 Governance deadlines'!$D$11>=M$7,'P2.1 Governance deadlines'!$D$11<=M$7+6),"UC meet ","")) | N5: =TRIM(IF(AND('P2.1 Governance deadlines'!$E$6>=N$7,'P2.1 Governance deadlines'!$E$6<=N$7+6),"Review Grp papers ","")&IF(AND('P2.1 Governance deadlines'!$D$6>=N$7,'P2.1 Governance deadlines'!$D$6<=N$7+6),"Review Grp meet ","")&IF(AND('P2.1 Governance deadlines'!$E$7>=N$7,'P2.1 Governance deadlines'!$E$7<=N$7+6),"VCAG papers ","")&IF(AND('P2.1 Governance deadlines'!$D$7>=N$7,'P2.1 Governance deadlines'!$D$7<=N$7+6),"VCAG meet ","")&IF(AND('P2.1 Governance deadlines'!$E$8>=N$7,'P2.1 Governance deadlines'!$E$8<=N$7+6),"IMC papers ","")&IF(AND('P2.1 Governance deadlines'!$D$8>=N$7,'P2.1 Governance deadlines'!$D$8<=N$7+6),"IMC meet ","")&IF(AND('P2.1 Governance deadlines'!$E$9>=N$7,'P2.1 Governance deadlines'!$E$9<=N$7+6),"VCAG papers ","")&IF(AND('P2.1 Governance deadlines'!$D$9>=N$7,'P2.1 Governance deadlines'!$D$9<=N$7+6),"VCAG meet ","")&IF(AND('P2.1 Governance deadlines'!$E$10>=N$7,'P2.1 Governance deadlines'!$E$10<=N$7+6),"UE papers ","")&IF(AND('P2.1 Governance deadlines'!$D$10>=N$7,'P2.1 Governance deadlines'!$D$10<=N$7+6),"UE meet ","")&IF(AND('P2.1 Governance deadlines'!$E$11>=N$7,'P2.1 Governance deadlines'!$E$11<=N$7+6),"UC papers ","")&IF(AND('P2.1 Governance deadlines'!$D$11>=N$7,'P2.1 Governance deadlines'!$D$11<=N$7+6),"UC meet ","")) | O5: =TRIM(IF(AND('P2.1 Governance deadlines'!$E$6>=O$7,'P2.1 Governance deadlines'!$E$6<=O$7+6),"Review Grp papers ","")&IF(AND('P2.1 Governance deadlines'!$D$6>=O$7,'P2.1 Governance deadlines'!$D$6<=O$7+6),"Review Grp meet ","")&IF(AND('P2.1 Governance deadlines'!$E$7>=O$7,'P2.1 Governance deadlines'!$E$7<=O$7+6),"VCAG papers ","")&IF(AND('P2.1 Governance deadlines'!$D$7>=O$7,'P2.1 Governance deadlines'!$D$7<=O$7+6),"VCAG meet ","")&IF(AND('P2.1 Governance deadlines'!$E$8>=O$7,'P2.1 Governance deadlines'!$E$8<=O$7+6),"IMC papers ","")&IF(AND('P2.1 Governance deadlines'!$D$8>=O$7,'P2.1 Governance deadlines'!$D$8<=O$7+6),"IMC meet ","")&IF(AND('P2.1 Governance deadlines'!$E$9>=O$7,'P2.1 Governance deadlines'!$E$9<=O$7+6),"VCAG papers ","")&IF(AND('P2.1 Governance deadlines'!$D$9>=O$7,'P2.1 Governance deadlines'!$D$9<=O$7+6),"VCAG meet ","")&IF(AND('P2.1 Governance deadlines'!$E$10>=O$7,'P2.1 Governance deadlines'!$E$10<=O$7+6),"UE papers ","")&IF(AND('P2.1 Governance deadlines'!$D$10>=O$7,'P2.1 Governance deadlines'!$D$10<=O$7+6),"UE meet ","")&IF(AND('P2.1 Governance deadlines'!$E$11>=O$7,'P2.1 Governance deadlines'!$E$11<=O$7+6),"UC papers ","")&IF(AND('P2.1 Governance deadlines'!$D$11>=O$7,'P2.1 Governance deadlines'!$D$11<=O$7+6),"UC meet ","")) | P5: =TRIM(IF(AND('P2.1 Governance deadlines'!$E$6>=P$7,'P2.1 Governance deadlines'!$E$6<=P$7+6),"Review Grp papers ","")&IF(AND('P2.1 Governance deadlines'!$D$6>=P$7,'P2.1 Governance deadlines'!$D$6<=P$7+6),"Review Grp meet ","")&IF(AND('P2.1 Governance deadlines'!$E$7>=P$7,'P2.1 Governance deadlines'!$E$7<=P$7+6),"VCAG papers ","")&IF(AND('P2.1 Governance deadlines'!$D$7>=P$7,'P2.1 Governance deadlines'!$D$7<=P$7+6),"VCAG meet ","")&IF(AND('P2.1 Governance deadlines'!$E$8>=P$7,'P2.1 Governance deadlines'!$E$8<=P$7+6),"IMC papers ","")&IF(AND('P2.1 Governance deadlines'!$D$8>=P$7,'P2.1 Governance deadlines'!$D$8<=P$7+6),"IMC meet ","")&IF(AND('P2.1 Governance deadlines'!$E$9>=P$7,'P2.1 Governance deadlines'!$E$9<=P$7+6),"VCAG papers ","")&IF(AND('P2.1 Governance deadlines'!$D$9>=P$7,'P2.1 Governance deadlines'!$D$9<=P$7+6),"VCAG meet ","")&IF(AND('P2.1 Governance deadlines'!$E$10>=P$7,'P2.1 Governance deadlines'!$E$10<=P$7+6),"UE papers ","")&IF(AND('P2.1 Governance deadlines'!$D$10>=P$7,'P2.1 Governance deadlines'!$D$10<=P$7+6),"UE meet ","")&IF(AND('P2.1 Governance deadlines'!$E$11>=P$7,'P2.1 Governance deadlines'!$E$11<=P$7+6),"UC papers ","")&IF(AND('P2.1 Governance deadlines'!$D$11>=P$7,'P2.1 Governance deadlines'!$D$11<=P$7+6),"UC meet ","")) | Q5: =TRIM(IF(AND('P2.1 Governance deadlines'!$E$6>=Q$7,'P2.1 Governance deadlines'!$E$6<=Q$7+6),"Review Grp papers ","")&IF(AND('P2.1 Governance deadlines'!$D$6>=Q$7,'P2.1 Governance deadlines'!$D$6<=Q$7+6),"Review Grp meet ","")&IF(AND('P2.1 Governance deadlines'!$E$7>=Q$7,'P2.1 Governance deadlines'!$E$7<=Q$7+6),"VCAG papers ","")&IF(AND('P2.1 Governance deadlines'!$D$7>=Q$7,'P2.1 Governance deadlines'!$D$7<=Q$7+6),"VCAG meet ","")&IF(AND('P2.1 Governance deadlines'!$E$8>=Q$7,'P2.1 Governance deadlines'!$E$8<=Q$7+6),"IMC papers ","")&IF(AND('P2.1 Governance deadlines'!$D$8>=Q$7,'P2.1 Governance deadlines'!$D$8<=Q$7+6),"IMC meet ","")&IF(AND('P2.1 Governance deadlines'!$E$9>=Q$7,'P2.1 Governance deadlines'!$E$9<=Q$7+6),"VCAG papers ","")&IF(AND('P2.1 Governance deadlines'!$D$9>=Q$7,'P2.1 Governance deadlines'!$D$9<=Q$7+6),"VCAG meet ","")&IF(AND('P2.1 Governance deadlines'!$E$10>=Q$7,'P2.1 Governance deadlines'!$E$10<=Q$7+6),"UE papers ","")&IF(AND('P2.1 Governance deadlines'!$D$10>=Q$7,'P2.1 Governance deadlines'!$D$10<=Q$7+6),"UE meet ","")&IF(AND('P2.1 Governance deadlines'!$E$11>=Q$7,'P2.1 Governance deadlines'!$E$11<=Q$7+6),"UC papers ","")&IF(AND('P2.1 Governance deadlines'!$D$11>=Q$7,'P2.1 Governance deadlines'!$D$11<=Q$7+6),"UC meet ","")) | R5: =TRIM(IF(AND('P2.1 Governance deadlines'!$E$6>=R$7,'P2.1 Governance deadlines'!$E$6<=R$7+6),"Review Grp papers ","")&IF(AND('P2.1 Governance deadlines'!$D$6>=R$7,'P2.1 Governance deadlines'!$D$6<=R$7+6),"Review Grp meet ","")&IF(AND('P2.1 Governance deadlines'!$E$7>=R$7,'P2.1 Governance deadlines'!$E$7<=R$7+6),"VCAG papers ","")&IF(AND('P2.1 Governance deadlines'!$D$7>=R$7,'P2.1 Governance deadlines'!$D$7<=R$7+6),"VCAG meet ","")&IF(AND('P2.1 Governance deadlines'!$E$8>=R$7,'P2.1 Governance deadlines'!$E$8<=R$7+6),"IMC papers ","")&IF(AND('P2.1 Governance deadlines'!$D$8>=R$7,'P2.1 Governance deadlines'!$D$8<=R$7+6),"IMC meet ","")&IF(AND('P2.1 Governance deadlines'!$E$9>=R$7,'P2.1 Governance deadlines'!$E$9<=R$7+6),"VCAG papers ","")&IF(AND('P2.1 Governance deadlines'!$D$9>=R$7,'P2.1 Governance deadlines'!$D$9<=R$7+6),"VCAG meet ","")&IF(AND('P2.1 Governance deadlines'!$E$10>=R$7,'P2.1 Governance deadlines'!$E$10<=R$7+6),"UE papers ","")&IF(AND('P2.1 Governance deadlines'!$D$10>=R$7,'P2.1 Governance deadlines'!$D$10<=R$7+6),"UE meet ","")&IF(AND('P2.1 Governance deadlines'!$E$11>=R$7,'P2.1 Governance deadlines'!$E$11<=R$7+6),"UC papers ","")&IF(AND('P2.1 Governance deadlines'!$D$11>=R$7,'P2.1 Governance deadlines'!$D$11<=R$7+6),"UC meet ","")) | S5: =TRIM(IF(AND('P2.1 Governance deadlines'!$E$6>=S$7,'P2.1 Governance deadlines'!$E$6<=S$7+6),"Review Grp papers ","")&IF(AND('P2.1 Governance deadlines'!$D$6>=S$7,'P2.1 Governance deadlines'!$D$6<=S$7+6),"Review Grp meet ","")&IF(AND('P2.1 Governance deadlines'!$E$7>=S$7,'P2.1 Governance deadlines'!$E$7<=S$7+6),"VCAG papers ","")&IF(AND('P2.1 Governance deadlines'!$D$7>=S$7,'P2.1 Governance deadlines'!$D$7<=S$7+6),"VCAG meet ","")&IF(AND('P2.1 Governance deadlines'!$E$8>=S$7,'P2.1 Governance deadlines'!$E$8<=S$7+6),"IMC papers ","")&IF(AND('P2.1 Governance deadlines'!$D$8>=S$7,'P2.1 Governance deadlines'!$D$8<=S$7+6),"IMC meet ","")&IF(AND('P2.1 Governance deadlines'!$E$9>=S$7,'P2.1 Governance deadlines'!$E$9<=S$7+6),"VCAG papers ","")&IF(AND('P2.1 Governance deadlines'!$D$9>=S$7,'P2.1 Governance deadlines'!$D$9<=S$7+6),"VCAG meet ","")&IF(AND('P2.1 Governance deadlines'!$E$10>=S$7,'P2.1 Governance deadlines'!$E$10<=S$7+6),"UE papers ","")&IF(AND('P2.1 Governance deadlines'!$D$10>=S$7,'P2.1 Governance deadlines'!$D$10<=S$7+6),"UE meet ","")&IF(AND('P2.1 Governance deadlines'!$E$11>=S$7,'P2.1 Governance deadlines'!$E$11<=S$7+6),"UC papers ","")&IF(AND('P2.1 Governance deadlines'!$D$11>=S$7,'P2.1 Governance deadlines'!$D$11<=S$7+6),"UC meet ","")) | ... AY5: =TRIM(IF(AND('P2.1 Governance deadlines'!$E$6>=AY$7,'P2.1 Governance deadlines'!$E$6<=AY$7+6),"Review Grp papers ","")&IF(AND('P2.1 Governance deadlines'!$D$6>=AY$7,'P2.1 Governance deadlines'!$D$6<=AY$7+6),"Review Grp meet ","")&IF(AND('P2.1 Governance deadlines'!$E$7>=AY$7,'P2.1 Governance deadlines'!$E$7<=AY$7+6),"VCAG papers ","")&IF(AND('P2.1 Governance deadlines'!$D$7>=AY$7,'P2.1 Governance deadlines'!$D$7<=AY$7+6),"VCAG meet ","")&IF(AND('P2.1 Governance deadlines'!$E$8>=AY$7,'P2.1 Governance deadlines'!$E$8<=AY$7+6),"IMC papers ","")&IF(AND('P2.1 Governance deadlines'!$D$8>=AY$7,'P2.1 Governance deadlines'!$D$8<=AY$7+6),"IMC meet ","")&IF(AND('P2.1 Governance deadlines'!$E$9>=AY$7,'P2.1 Governance deadlines'!$E$9<=AY$7+6),"VCAG papers ","")&IF(AND('P2.1 Governance deadlines'!$D$9>=AY$7,'P2.1 Governance deadlines'!$D$9<=AY$7+6),"VCAG meet ","")&IF(AND('P2.1 Governance deadlines'!$E$10>=AY$7,'P2.1 Governance deadlines'!$E$10<=AY$7+6),"UE papers ","")&IF(AND('P2.1 Governance deadlines'!$D$10>=AY$7,'P2.1 Governance deadlines'!$D$10<=AY$7+6),"UE meet ","")&IF(AND('P2.1 Governance deadlines'!$E$11>=AY$7,'P2.1 Governance deadlines'!$E$11<=AY$7+6),"UC papers ","")&IF(AND('P2.1 Governance deadlines'!$D$11>=AY$7,'P2.1 Governance deadlines'!$D$11<=AY$7+6),"UC meet ",""))
L6: Oct 2026 | P6: Nov | U6: Dec | Y6: Jan 2027 | AC6: Feb | AG6: Mar | AL6: Apr | AP6: May | AU6: Jun | AY6: Jul
B7: Phase / key activity | C7: Key milestone | D7: Start | E7: End | F7: When | G7: Lead (R) | H7: Accountable (A) | I7: Priority | J7: Status | L7: 46300 | M7: 46307 | N7: 46314 | O7: 46321 | P7: 46328 | Q7: 46335 | R7: 46342 | S7: 46349 | T7: 46356 | U7: 46363 | V7: 46370 | W7: 46377 | X7: 46384 | Y7: 46391 | Z7: 46398 | AA7: 46405 | AB7: 46412 | AC7: 46419 | AD7: 46426 | AE7: 46433 | AF7: 46440 | AG7: 46447 | AH7: 46454 | AI7: 46461 | AJ7: 46468 | AK7: 46475 | AL7: 46482 | AM7: 46489 | AN7: 46496 | AO7: 46503 | AP7: 46510 | AQ7: 46517 | AR7: 46524 | AS7: 46531 | AT7: 46538 | AU7: 46545 | AV7: 46552 | AW7: 46559 | AX7: 46566 | AY7: 46573
B8: Project set-up (Sep–Oct 2026)
B9: Confirm scope, reporting model, governance pathway and decisions | C9: Decision log | D9: 46279 | E9: 46311 | F9: =IF(D9="","",TEXT(D9,"d mmm")&IF(E9<>D9," – "&TEXT(E9,"d mmm"),"")) | G9: {=_xlfn.TEXTJOIN(", ",TRUE,IF(ISNUMBER(SEARCH("R",'P2.3 RASCI matrix'!$H9:$Z9)),'P2.3 RASCI matrix'!$H$7:$Z$7,""))} | H9: {=_xlfn.TEXTJOIN(", ",TRUE,IF(LEFT('P2.3 RASCI matrix'!$H9:$Z9,1)="A",'P2.3 RASCI matrix'!$H$7:$Z$7,""))} | I9: High | J9: Not yet started
B10: Project charter, schedule, RASCI, decision log, issues register | C10: Approved by Oct | D10: 46293 | E10: 46318 | F10: =IF(D10="","",TEXT(D10,"d mmm")&IF(E10<>D10," – "&TEXT(E10,"d mmm"),"")) | G10: {=_xlfn.TEXTJOIN(", ",TRUE,IF(ISNUMBER(SEARCH("R",'P2.3 RASCI matrix'!$H10:$Z10)),'P2.3 RASCI matrix'!$H$7:$Z$7,""))} | H10: {=_xlfn.TEXTJOIN(", ",TRUE,IF(LEFT('P2.3 RASCI matrix'!$H10:$Z10,1)="A",'P2.3 RASCI matrix'!$H$7:$Z$7,""))} | I10: High | J10: Not yet started
B11: Map refreshed targets/indicators to Databook, systems, owners | C11: Requirements matrix | D11: 46286 | E11: 46311 | F11: =IF(D11="","",TEXT(D11,"d mmm")&IF(E11<>D11," – "&TEXT(E11,"d mmm"),"")) | G11: {=_xlfn.TEXTJOIN(", ",TRUE,IF(ISNUMBER(SEARCH("R",'P2.3 RASCI matrix'!$H11:$Z11)),'P2.3 RASCI matrix'!$H$7:$Z$7,""))} | H11: {=_xlfn.TEXTJOIN(", ",TRUE,IF(LEFT('P2.3 RASCI matrix'!$H11:$Z11,1)="A",'P2.3 RASCI matrix'!$H$7:$Z$7,""))} | I11: High | J11: Not yet started
B12: Confirm stakeholder structure (CGOP/CDEP) and owners (Gerard: resilience, estate) | C12: Stakeholder map | D12: 46300 | E12: 46311 | F12: =IF(D12="","",TEXT(D12,"d mmm")&IF(E12<>D12," – "&TEXT(E12,"d mmm"),"")) | G12: {=_xlfn.TEXTJOIN(", ",TRUE,IF(ISNUMBER(SEARCH("R",'P2.3 RASCI matrix'!$H12:$Z12)),'P2.3 RASCI matrix'!$H$7:$Z$7,""))} | H12: {=_xlfn.TEXTJOIN(", ",TRUE,IF(LEFT('P2.3 RASCI matrix'!$H12:$Z12,1)="A",'P2.3 RASCI matrix'!$H$7:$Z$7,""))} | I12: High | J12: Not yet started
B13: Test request templates (ABP walkthrough) and Teams workbook links | C13: Templates and links tested | D13: 46307 | E13: 46325 | F13: =IF(D13="","",TEXT(D13,"d mmm")&IF(E13<>D13," – "&TEXT(E13,"d mmm"),"")) | G13: {=_xlfn.TEXTJOIN(", ",TRUE,IF(ISNUMBER(SEARCH("R",'P2.3 RASCI matrix'!$H13:$Z13)),'P2.3 RASCI matrix'!$H$7:$Z$7,""))} | H13: {=_xlfn.TEXTJOIN(", ",TRUE,IF(LEFT('P2.3 RASCI matrix'!$H13:$Z13,1)="A",'P2.3 RASCI matrix'!$H$7:$Z$7,""))} | I13: High | J13: Not yet started
B14: Approve Review Group criteria, decision rights, escalation pathway | C14: Before collection | D14: 46300 | E14: 46325 | F14: =IF(D14="","",TEXT(D14,"d mmm")&IF(E14<>D14," – "&TEXT(E14,"d mmm"),"")) | G14: {=_xlfn.TEXTJOIN(", ",TRUE,IF(ISNUMBER(SEARCH("R",'P2.3 RASCI matrix'!$H14:$Z14)),'P2.3 RASCI matrix'!$H$7:$Z$7,""))} | H14: {=_xlfn.TEXTJOIN(", ",TRUE,IF(LEFT('P2.3 RASCI matrix'!$H14:$Z14,1)="A",'P2.3 RASCI matrix'!$H$7:$Z$7,""))} | I14: Medium | J14: Not yet started
B15: Process design & launch (Oct 2026)
B16: Finalise templates and evidence register | C16: Templates final | D16: 46314 | E16: 46325 | F16: =IF(D16="","",TEXT(D16,"d mmm")&IF(E16<>D16," – "&TEXT(E16,"d mmm"),"")) | G16: {=_xlfn.TEXTJOIN(", ",TRUE,IF(ISNUMBER(SEARCH("R",'P2.3 RASCI matrix'!$H16:$Z16)),'P2.3 RASCI matrix'!$H$7:$Z$7,""))} | H16: {=_xlfn.TEXTJOIN(", ",TRUE,IF(LEFT('P2.3 RASCI matrix'!$H16:$Z16,1)="A",'P2.3 RASCI matrix'!$H$7:$Z$7,""))} | I16: High | J16: Not yet started
B17: Coordinate with University Annual Report team (dependency map) | C17: Shared data map | D17: 46300 | E17: 46325 | F17: =IF(D17="","",TEXT(D17,"d mmm")&IF(E17<>D17," – "&TEXT(E17,"d mmm"),"")) | G17: {=_xlfn.TEXTJOIN(", ",TRUE,IF(ISNUMBER(SEARCH("R",'P2.3 RASCI matrix'!$H17:$Z17)),'P2.3 RASCI matrix'!$H$7:$Z$7,""))} | H17: {=_xlfn.TEXTJOIN(", ",TRUE,IF(LEFT('P2.3 RASCI matrix'!$H17:$Z17,1)="A",'P2.3 RASCI matrix'!$H$7:$Z$7,""))} | I17: High | J17: Not yet started
B18: Convene Strategic Comms, digital & design; agree comms RASCI | C18: Kick-off | D18: 46300 | E18: 46318 | F18: =IF(D18="","",TEXT(D18,"d mmm")&IF(E18<>D18," – "&TEXT(E18,"d mmm"),"")) | G18: {=_xlfn.TEXTJOIN(", ",TRUE,IF(ISNUMBER(SEARCH("R",'P2.3 RASCI matrix'!$H18:$Z18)),'P2.3 RASCI matrix'!$H$7:$Z$7,""))} | H18: {=_xlfn.TEXTJOIN(", ",TRUE,IF(LEFT('P2.3 RASCI matrix'!$H18:$Z18,1)="A",'P2.3 RASCI matrix'!$H$7:$Z$7,""))} | I18: High | J18: Not yet started
B19: Sustainability 2030 launch | C19: ~20 Oct (TBC) | D19: 46315 | E19: 46315 | F19: =IF(D19="","",TEXT(D19,"d mmm")&IF(E19<>D19," – "&TEXT(E19,"d mmm"),"")) | G19: {=_xlfn.TEXTJOIN(", ",TRUE,IF(ISNUMBER(SEARCH("R",'P2.3 RASCI matrix'!$H19:$Z19)),'P2.3 RASCI matrix'!$H$7:$Z$7,""))} | H19: {=_xlfn.TEXTJOIN(", ",TRUE,IF(LEFT('P2.3 RASCI matrix'!$H19:$Z19,1)="A",'P2.3 RASCI matrix'!$H$7:$Z$7,""))} | I19: Milestone | J19: Not yet started | L19: =IF(AND(L$7+6>=$D19,L$7<=$E19),"◆","") | M19: =IF(AND(M$7+6>=$D19,M$7<=$E19),"◆","") | N19: =IF(AND(N$7+6>=$D19,N$7<=$E19),"◆","") | O19: =IF(AND(O$7+6>=$D19,O$7<=$E19),"◆","") | P19: =IF(AND(P$7+6>=$D19,P$7<=$E19),"◆","") | Q19: =IF(AND(Q$7+6>=$D19,Q$7<=$E19),"◆","") | R19: =IF(AND(R$7+6>=$D19,R$7<=$E19),"◆","") | S19: =IF(AND(S$7+6>=$D19,S$7<=$E19),"◆","") | ... AY19: =IF(AND(AY$7+6>=$D19,AY$7<=$E19),"◆","")
B20: Brief contributor groups / working groups (after launch) | D20: 46315 | E20: 46332 | F20: =IF(D20="","",TEXT(D20,"d mmm")&IF(E20<>D20," – "&TEXT(E20,"d mmm"),"")) | G20: {=_xlfn.TEXTJOIN(", ",TRUE,IF(ISNUMBER(SEARCH("R",'P2.3 RASCI matrix'!$H20:$Z20)),'P2.3 RASCI matrix'!$H$7:$Z$7,""))} | H20: {=_xlfn.TEXTJOIN(", ",TRUE,IF(LEFT('P2.3 RASCI matrix'!$H20:$Z20,1)="A",'P2.3 RASCI matrix'!$H$7:$Z$7,""))} | I20: Medium | J20: Not yet started
B21: Joint ADs Sustainability & ADs T&L session | C21: Structured prompt in advance | D21: 46314 | E21: 46325 | F21: =IF(D21="","",TEXT(D21,"d mmm")&IF(E21<>D21," – "&TEXT(E21,"d mmm"),"")) | G21: {=_xlfn.TEXTJOIN(", ",TRUE,IF(ISNUMBER(SEARCH("R",'P2.3 RASCI matrix'!$H21:$Z21)),'P2.3 RASCI matrix'!$H$7:$Z$7,""))} | H21: {=_xlfn.TEXTJOIN(", ",TRUE,IF(LEFT('P2.3 RASCI matrix'!$H21:$Z21,1)="A",'P2.3 RASCI matrix'!$H$7:$Z$7,""))} | I21: Medium | J21: Not yet started
B22: Early engagement: socialise requirements in existing meetings (esp. education-related) | C22: Stakeholder awareness | D22: 46321 | E22: 46325 | F22: =IF(D22="","",TEXT(D22,"d mmm")&IF(E22<>D22," – "&TEXT(E22,"d mmm"),"")) | G22: {=_xlfn.TEXTJOIN(", ",TRUE,IF(ISNUMBER(SEARCH("R",'P2.3 RASCI matrix'!$H22:$Z22)),'P2.3 RASCI matrix'!$H$7:$Z$7,""))} | H22: {=_xlfn.TEXTJOIN(", ",TRUE,IF(LEFT('P2.3 RASCI matrix'!$H22:$Z22,1)="A",'P2.3 RASCI matrix'!$H$7:$Z$7,""))} | I22: High | J22: Not yet started
B23: Collection & evidence (Nov–Dec 2026)
B24: Collection launch: issue tailored requests (separate workbook per faculty/unit) | C24: Requests formally issued | D24: 46328 | E24: 46332 | F24: =IF(D24="","",TEXT(D24,"d mmm")&IF(E24<>D24," – "&TEXT(E24,"d mmm"),"")) | G24: {=_xlfn.TEXTJOIN(", ",TRUE,IF(ISNUMBER(SEARCH("R",'P2.3 RASCI matrix'!$H24:$Z24)),'P2.3 RASCI matrix'!$H$7:$Z$7,""))} | H24: {=_xlfn.TEXTJOIN(", ",TRUE,IF(LEFT('P2.3 RASCI matrix'!$H24:$Z24,1)="A",'P2.3 RASCI matrix'!$H$7:$Z$7,""))} | I24: High | J24: Not yet started
B25: Collection period: stakeholders prepare responses and evidence | C25: Initial submission | D25: 46328 | E25: 46371 | F25: =IF(D25="","",TEXT(D25,"d mmm")&IF(E25<>D25," – "&TEXT(E25,"d mmm"),"")) | G25: {=_xlfn.TEXTJOIN(", ",TRUE,IF(ISNUMBER(SEARCH("R",'P2.3 RASCI matrix'!$H25:$Z25)),'P2.3 RASCI matrix'!$H$7:$Z$7,""))} | H25: {=_xlfn.TEXTJOIN(", ",TRUE,IF(LEFT('P2.3 RASCI matrix'!$H25:$Z25,1)="A",'P2.3 RASCI matrix'!$H$7:$Z$7,""))} | I25: High | J25: Not yet started
B26: SST answers questions and records clarifications centrally | C26: Clarifications log | D26: 46328 | E26: 46371 | F26: =IF(D26="","",TEXT(D26,"d mmm")&IF(E26<>D26," – "&TEXT(E26,"d mmm"),"")) | G26: {=_xlfn.TEXTJOIN(", ",TRUE,IF(ISNUMBER(SEARCH("R",'P2.3 RASCI matrix'!$H26:$Z26)),'P2.3 RASCI matrix'!$H$7:$Z$7,""))} | H26: {=_xlfn.TEXTJOIN(", ",TRUE,IF(LEFT('P2.3 RASCI matrix'!$H26:$Z26,1)="A",'P2.3 RASCI matrix'!$H$7:$Z$7,""))} | I26: Medium | J26: Not yet started
B27: Optional 1:1 meetings (on request) | D27: 46328 | E27: 46371 | F27: =IF(D27="","",TEXT(D27,"d mmm")&IF(E27<>D27," – "&TEXT(E27,"d mmm"),"")) | G27: {=_xlfn.TEXTJOIN(", ",TRUE,IF(ISNUMBER(SEARCH("R",'P2.3 RASCI matrix'!$H27:$Z27)),'P2.3 RASCI matrix'!$H$7:$Z$7,""))} | H27: {=_xlfn.TEXTJOIN(", ",TRUE,IF(LEFT('P2.3 RASCI matrix'!$H27:$Z27,1)="A",'P2.3 RASCI matrix'!$H$7:$Z$7,""))} | I27: Medium | J27: Not yet started
B28: Responses and highlighted stories due (Christmas shutdown) | C28: 24 Dec | D28: 46380 | E28: 46380 | F28: =IF(D28="","",TEXT(D28,"d mmm")&IF(E28<>D28," – "&TEXT(E28,"d mmm"),"")) | G28: {=_xlfn.TEXTJOIN(", ",TRUE,IF(ISNUMBER(SEARCH("R",'P2.3 RASCI matrix'!$H28:$Z28)),'P2.3 RASCI matrix'!$H$7:$Z$7,""))} | H28: {=_xlfn.TEXTJOIN(", ",TRUE,IF(LEFT('P2.3 RASCI matrix'!$H28:$Z28,1)="A",'P2.3 RASCI matrix'!$H$7:$Z$7,""))} | I28: Milestone | J28: Not yet started | L28: =IF(AND(L$7+6>=$D28,L$7<=$E28),"◆","") | M28: =IF(AND(M$7+6>=$D28,M$7<=$E28),"◆","") | N28: =IF(AND(N$7+6>=$D28,N$7<=$E28),"◆","") | O28: =IF(AND(O$7+6>=$D28,O$7<=$E28),"◆","") | P28: =IF(AND(P$7+6>=$D28,P$7<=$E28),"◆","") | Q28: =IF(AND(Q$7+6>=$D28,Q$7<=$E28),"◆","") | R28: =IF(AND(R$7+6>=$D28,R$7<=$E28),"◆","") | S28: =IF(AND(S$7+6>=$D28,S$7<=$E28),"◆","") | ... AY28: =IF(AND(AY$7+6>=$D28,AY$7<=$E28),"◆","")
B29: Drafting, validation & governance papers (Jan–May 2027)
B30: First review: completeness and evidence quality | C30: First QA assessment | D30: 46391 | E30: 46395 | F30: =IF(D30="","",TEXT(D30,"d mmm")&IF(E30<>D30," – "&TEXT(E30,"d mmm"),"")) | G30: {=_xlfn.TEXTJOIN(", ",TRUE,IF(ISNUMBER(SEARCH("R",'P2.3 RASCI matrix'!$H30:$Z30)),'P2.3 RASCI matrix'!$H$7:$Z$7,""))} | H30: {=_xlfn.TEXTJOIN(", ",TRUE,IF(LEFT('P2.3 RASCI matrix'!$H30:$Z30,1)="A",'P2.3 RASCI matrix'!$H$7:$Z$7,""))} | I30: High | J30: Not yet started
B31: Targeted follow-up where evidence is incomplete, ambiguous or missing (no second broad request; ask availability) | C31: Resolved gaps | D31: 46391 | E31: 46402 | F31: =IF(D31="","",TEXT(D31,"d mmm")&IF(E31<>D31," – "&TEXT(E31,"d mmm"),"")) | G31: {=_xlfn.TEXTJOIN(", ",TRUE,IF(ISNUMBER(SEARCH("R",'P2.3 RASCI matrix'!$H31:$Z31)),'P2.3 RASCI matrix'!$H$7:$Z$7,""))} | H31: {=_xlfn.TEXTJOIN(", ",TRUE,IF(LEFT('P2.3 RASCI matrix'!$H31:$Z31,1)="A",'P2.3 RASCI matrix'!$H$7:$Z$7,""))} | I31: High | J31: Not yet started
B32: Consolidation: finalise master, identify unresolved gaps, prepare drafting material | C32: Consolidated master spreadsheet | D32: 46405 | E32: 46409 | F32: =IF(D32="","",TEXT(D32,"d mmm")&IF(E32<>D32," – "&TEXT(E32,"d mmm"),"")) | G32: {=_xlfn.TEXTJOIN(", ",TRUE,IF(ISNUMBER(SEARCH("R",'P2.3 RASCI matrix'!$H32:$Z32)),'P2.3 RASCI matrix'!$H$7:$Z$7,""))} | H32: {=_xlfn.TEXTJOIN(", ",TRUE,IF(LEFT('P2.3 RASCI matrix'!$H32:$Z32,1)="A",'P2.3 RASCI matrix'!$H$7:$Z$7,""))} | I32: High | J32: Not yet started
B33: Confirm final quantitative figures (Databook) | D33: 46391 | E33: 46416 | F33: =IF(D33="","",TEXT(D33,"d mmm")&IF(E33<>D33," – "&TEXT(E33,"d mmm"),"")) | G33: {=_xlfn.TEXTJOIN(", ",TRUE,IF(ISNUMBER(SEARCH("R",'P2.3 RASCI matrix'!$H33:$Z33)),'P2.3 RASCI matrix'!$H$7:$Z$7,""))} | H33: {=_xlfn.TEXTJOIN(", ",TRUE,IF(LEFT('P2.3 RASCI matrix'!$H33:$Z33,1)="A",'P2.3 RASCI matrix'!$H$7:$Z$7,""))} | I33: High | J33: Not yet started
B34: Review responses by indicator (A1 / T1 / T2) – no target status rating in 2026 | D34: 46405 | E34: 46416 | F34: =IF(D34="","",TEXT(D34,"d mmm")&IF(E34<>D34," – "&TEXT(E34,"d mmm"),"")) | G34: {=_xlfn.TEXTJOIN(", ",TRUE,IF(ISNUMBER(SEARCH("R",'P2.3 RASCI matrix'!$H34:$Z34)),'P2.3 RASCI matrix'!$H$7:$Z$7,""))} | H34: {=_xlfn.TEXTJOIN(", ",TRUE,IF(LEFT('P2.3 RASCI matrix'!$H34:$Z34,1)="A",'P2.3 RASCI matrix'!$H$7:$Z$7,""))} | I34: High | J34: Not yet started
B35: Drafting from consolidated master; full draft + issues paper | D35: 46405 | E35: 46423 | F35: =IF(D35="","",TEXT(D35,"d mmm")&IF(E35<>D35," – "&TEXT(E35,"d mmm"),"")) | G35: {=_xlfn.TEXTJOIN(", ",TRUE,IF(ISNUMBER(SEARCH("R",'P2.3 RASCI matrix'!$H35:$Z35)),'P2.3 RASCI matrix'!$H$7:$Z$7,""))} | H35: {=_xlfn.TEXTJOIN(", ",TRUE,IF(LEFT('P2.3 RASCI matrix'!$H35:$Z35,1)="A",'P2.3 RASCI matrix'!$H$7:$Z$7,""))} | I35: High | J35: Not yet started
B36: Draft paper: Sustainability Reporting Review Group – review findings | C36: Begin drafting → leaders | D36: ='P2.1 Governance deadlines'!G6 | E36: ='P2.1 Governance deadlines'!F6 | F36: =IF(D36="","",TEXT(D36,"d mmm")&IF(E36<>D36," – "&TEXT(E36,"d mmm"),"")) | G36: {=_xlfn.TEXTJOIN(", ",TRUE,IF(ISNUMBER(SEARCH("R",'P2.3 RASCI matrix'!$H36:$Z36)),'P2.3 RASCI matrix'!$H$7:$Z$7,""))} | H36: {=_xlfn.TEXTJOIN(", ",TRUE,IF(LEFT('P2.3 RASCI matrix'!$H36:$Z36,1)="A",'P2.3 RASCI matrix'!$H$7:$Z$7,""))} | I36: High | J36: Not yet started
B37: Papers due: Sustainability Reporting Review Group – review findings | C37: Papers due | D37: ='P2.1 Governance deadlines'!E6 | E37: ='P2.1 Governance deadlines'!E6 | F37: =IF(D37="","",TEXT(D37,"d mmm")&IF(E37<>D37," – "&TEXT(E37,"d mmm"),"")) | G37: {=_xlfn.TEXTJOIN(", ",TRUE,IF(ISNUMBER(SEARCH("R",'P2.3 RASCI matrix'!$H37:$Z37)),'P2.3 RASCI matrix'!$H$7:$Z$7,""))} | H37: {=_xlfn.TEXTJOIN(", ",TRUE,IF(LEFT('P2.3 RASCI matrix'!$H37:$Z37,1)="A",'P2.3 RASCI matrix'!$H$7:$Z$7,""))} | I37: Milestone | J37: Not yet started | L37: =IF(AND(L$7+6>=$D37,L$7<=$E37),"◆","") | M37: =IF(AND(M$7+6>=$D37,M$7<=$E37),"◆","") | N37: =IF(AND(N$7+6>=$D37,N$7<=$E37),"◆","") | O37: =IF(AND(O$7+6>=$D37,O$7<=$E37),"◆","") | P37: =IF(AND(P$7+6>=$D37,P$7<=$E37),"◆","") | Q37: =IF(AND(Q$7+6>=$D37,Q$7<=$E37),"◆","") | R37: =IF(AND(R$7+6>=$D37,R$7<=$E37),"◆","") | S37: =IF(AND(S$7+6>=$D37,S$7<=$E37),"◆","") | ... AY37: =IF(AND(AY$7+6>=$D37,AY$7<=$E37),"◆","")
B38: Meeting: Sustainability Reporting Review Group – review findings | C38: Meeting | D38: ='P2.1 Governance deadlines'!D6 | E38: ='P2.1 Governance deadlines'!D6 | F38: =IF(D38="","",TEXT(D38,"d mmm")&IF(E38<>D38," – "&TEXT(E38,"d mmm"),"")) | G38: {=_xlfn.TEXTJOIN(", ",TRUE,IF(ISNUMBER(SEARCH("R",'P2.3 RASCI matrix'!$H38:$Z38)),'P2.3 RASCI matrix'!$H$7:$Z$7,""))} | H38: {=_xlfn.TEXTJOIN(", ",TRUE,IF(LEFT('P2.3 RASCI matrix'!$H38:$Z38,1)="A",'P2.3 RASCI matrix'!$H$7:$Z$7,""))} | I38: Milestone | J38: Not yet started | L38: =IF(AND(L$7+6>=$D38,L$7<=$E38),"◆","") | M38: =IF(AND(M$7+6>=$D38,M$7<=$E38),"◆","") | N38: =IF(AND(N$7+6>=$D38,N$7<=$E38),"◆","") | O38: =IF(AND(O$7+6>=$D38,O$7<=$E38),"◆","") | P38: =IF(AND(P$7+6>=$D38,P$7<=$E38),"◆","") | Q38: =IF(AND(Q$7+6>=$D38,Q$7<=$E38),"◆","") | R38: =IF(AND(R$7+6>=$D38,R$7<=$E38),"◆","") | S38: =IF(AND(S$7+6>=$D38,S$7<=$E38),"◆","") | ... AY38: =IF(AND(AY$7+6>=$D38,AY$7<=$E38),"◆","")
B39: Draft paper: VCAG – notes review group findings | C39: Begin drafting → leaders | D39: ='P2.1 Governance deadlines'!G7 | E39: ='P2.1 Governance deadlines'!F7 | F39: =IF(D39="","",TEXT(D39,"d mmm")&IF(E39<>D39," – "&TEXT(E39,"d mmm"),"")) | G39: {=_xlfn.TEXTJOIN(", ",TRUE,IF(ISNUMBER(SEARCH("R",'P2.3 RASCI matrix'!$H39:$Z39)),'P2.3 RASCI matrix'!$H$7:$Z$7,""))} | H39: {=_xlfn.TEXTJOIN(", ",TRUE,IF(LEFT('P2.3 RASCI matrix'!$H39:$Z39,1)="A",'P2.3 RASCI matrix'!$H$7:$Z$7,""))} | I39: High | J39: Not yet started
B40: Papers due: VCAG – notes review group findings | C40: Papers due | D40: ='P2.1 Governance deadlines'!E7 | E40: ='P2.1 Governance deadlines'!E7 | F40: =IF(D40="","",TEXT(D40,"d mmm")&IF(E40<>D40," – "&TEXT(E40,"d mmm"),"")) | G40: {=_xlfn.TEXTJOIN(", ",TRUE,IF(ISNUMBER(SEARCH("R",'P2.3 RASCI matrix'!$H40:$Z40)),'P2.3 RASCI matrix'!$H$7:$Z$7,""))} | H40: {=_xlfn.TEXTJOIN(", ",TRUE,IF(LEFT('P2.3 RASCI matrix'!$H40:$Z40,1)="A",'P2.3 RASCI matrix'!$H$7:$Z$7,""))} | I40: Milestone | J40: Not yet started | L40: =IF(AND(L$7+6>=$D40,L$7<=$E40),"◆","") | M40: =IF(AND(M$7+6>=$D40,M$7<=$E40),"◆","") | N40: =IF(AND(N$7+6>=$D40,N$7<=$E40),"◆","") | O40: =IF(AND(O$7+6>=$D40,O$7<=$E40),"◆","") | P40: =IF(AND(P$7+6>=$D40,P$7<=$E40),"◆","") | Q40: =IF(AND(Q$7+6>=$D40,Q$7<=$E40),"◆","") | R40: =IF(AND(R$7+6>=$D40,R$7<=$E40),"◆","") | S40: =IF(AND(S$7+6>=$D40,S$7<=$E40),"◆","") | ... AY40: =IF(AND(AY$7+6>=$D40,AY$7<=$E40),"◆","")
B41: Meeting: VCAG – notes review group findings | C41: Meeting | D41: ='P2.1 Governance deadlines'!D7 | E41: ='P2.1 Governance deadlines'!D7 | F41: =IF(D41="","",TEXT(D41,"d mmm")&IF(E41<>D41," – "&TEXT(E41,"d mmm"),"")) | G41: {=_xlfn.TEXTJOIN(", ",TRUE,IF(ISNUMBER(SEARCH("R",'P2.3 RASCI matrix'!$H41:$Z41)),'P2.3 RASCI matrix'!$H$7:$Z$7,""))} | H41: {=_xlfn.TEXTJOIN(", ",TRUE,IF(LEFT('P2.3 RASCI matrix'!$H41:$Z41,1)="A",'P2.3 RASCI matrix'!$H$7:$Z$7,""))} | I41: Milestone | J41: Not yet started | L41: =IF(AND(L$7+6>=$D41,L$7<=$E41),"◆","") | M41: =IF(AND(M$7+6>=$D41,M$7<=$E41),"◆","") | N41: =IF(AND(N$7+6>=$D41,N$7<=$E41),"◆","") | O41: =IF(AND(O$7+6>=$D41,O$7<=$E41),"◆","") | P41: =IF(AND(P$7+6>=$D41,P$7<=$E41),"◆","") | Q41: =IF(AND(Q$7+6>=$D41,Q$7<=$E41),"◆","") | R41: =IF(AND(R$7+6>=$D41,R$7<=$E41),"◆","") | S41: =IF(AND(S$7+6>=$D41,S$7<=$E41),"◆","") | ... AY41: =IF(AND(AY$7+6>=$D41,AY$7<=$E41),"◆","")
B42: Draft paper: Investment Management Committee – responsible investments section | C42: Begin drafting → leaders | D42: ='P2.1 Governance deadlines'!G8 | E42: ='P2.1 Governance deadlines'!F8 | F42: =IF(D42="","",TEXT(D42,"d mmm")&IF(E42<>D42," – "&TEXT(E42,"d mmm"),"")) | G42: {=_xlfn.TEXTJOIN(", ",TRUE,IF(ISNUMBER(SEARCH("R",'P2.3 RASCI matrix'!$H42:$Z42)),'P2.3 RASCI matrix'!$H$7:$Z$7,""))} | H42: {=_xlfn.TEXTJOIN(", ",TRUE,IF(LEFT('P2.3 RASCI matrix'!$H42:$Z42,1)="A",'P2.3 RASCI matrix'!$H$7:$Z$7,""))} | I42: High | J42: Not yet started
...

Sheet P2.3 RASCI matrix
B2: P2.3 RASCI matrix – who does what
B3: A = Accountable (signs off) • R = Responsible (does the work) • S = Support • C = Consulted • I = Informed. Edit with the dropdown; Lead (R) and Accountable (A) on P2.2 Timeline update automatically. Rows match P2.2 Timeline row for row.
G5: Group >> | H5: SST | I5: SST | J5: SST | K5: Leadership | L5: Leadership | M5: Leadership | N5: Governance | O5: Governance | P5: Governance | Q5: Governance | R5: Governance | S5: Comms & web | T5: Comms & web | U5: Contributors | V5: Contributors | W5: Contributors | X5: Contributors
G6: Contact >> | H6: Sustainability Strategy team | I6: Stefanus | J6: Rose Hawkins | K6: Gerard Healey | L6: Director | M6: COO | N6: Convenor TBC | U6: ADs
B7: No. | C7: Phase / key activity | D7: Key milestone | E7: When | F7: Status | G7: Activity area >> | H7: SST (team) | I7: Stefanus | J7: Rose | K7: Gerard Healey | L7: Director, Sustainability | M7: COO (sponsor) | N7: Review Group | O7: VCAG | P7: IMC | Q7: University Executive | R7: University Council | S7: Strategic Comms | T7: Comms / digital / design | U7: Faculties (ADs Sustainability) | V7: Central data owners | W7: Working groups | X7: Annual Report team
C8: Project set-up (Sep–Oct 2026)
B9: 1 | C9: ='P2.2 Timeline'!B9 | D9: ='P2.2 Timeline'!C9 | E9: ='P2.2 Timeline'!F9 | F9: ='P2.2 Timeline'!J9 | H9: R | L9: A | O9: I
B10: 2 | C10: ='P2.2 Timeline'!B10 | D10: ='P2.2 Timeline'!C10 | E10: ='P2.2 Timeline'!F10 | F10: ='P2.2 Timeline'!J10 | H10: R | L10: A | T10: C
B11: 3 | C11: ='P2.2 Timeline'!B11 | D11: ='P2.2 Timeline'!C11 | E11: ='P2.2 Timeline'!F11 | F11: ='P2.2 Timeline'!J11 | I11: R | J11: S | K11: A | V11: C
B12: 4 | C12: ='P2.2 Timeline'!B12 | D12: ='P2.2 Timeline'!C12 | E12: ='P2.2 Timeline'!F12 | F12: ='P2.2 Timeline'!J12 | I12: R | K12: A
B13: 5 | C13: ='P2.2 Timeline'!B13 | D13: ='P2.2 Timeline'!C13 | E13: ='P2.2 Timeline'!F13 | F13: ='P2.2 Timeline'!J13 | I13: R | K13: A | U13: C
B14: 6 | C14: ='P2.2 Timeline'!B14 | D14: ='P2.2 Timeline'!C14 | E14: ='P2.2 Timeline'!F14 | F14: ='P2.2 Timeline'!J14 | H14: R | L14: A | N14: C
C15: Process design & launch (Oct 2026)
B16: 7 | C16: ='P2.2 Timeline'!B16 | D16: ='P2.2 Timeline'!C16 | E16: ='P2.2 Timeline'!F16 | F16: ='P2.2 Timeline'!J16 | I16: R | K16: A
B17: 8 | C17: ='P2.2 Timeline'!B17 | D17: ='P2.2 Timeline'!C17 | E17: ='P2.2 Timeline'!F17 | F17: ='P2.2 Timeline'!J17 | H17: R | L17: A | X17: C
B18: 9 | C18: ='P2.2 Timeline'!B18 | D18: ='P2.2 Timeline'!C18 | E18: ='P2.2 Timeline'!F18 | F18: ='P2.2 Timeline'!J18 | H18: R | L18: A | S18: S | T18: C
B19: 10 | C19: ='P2.2 Timeline'!B19 | D19: ='P2.2 Timeline'!C19 | E19: ='P2.2 Timeline'!F19 | F19: ='P2.2 Timeline'!J19
B20: 11 | C20: ='P2.2 Timeline'!B20 | D20: ='P2.2 Timeline'!C20 | E20: ='P2.2 Timeline'!F20 | F20: ='P2.2 Timeline'!J20 | H20: R | W20: C
B21: 12 | C21: ='P2.2 Timeline'!B21 | D21: ='P2.2 Timeline'!C21 | E21: ='P2.2 Timeline'!F21 | F21: ='P2.2 Timeline'!J21 | H21: R | U21: C
B22: 13 | C22: ='P2.2 Timeline'!B22 | D22: ='P2.2 Timeline'!C22 | E22: ='P2.2 Timeline'!F22 | F22: ='P2.2 Timeline'!J22 | H22: R | U22: C | V22: C
C23: Collection & evidence (Nov–Dec 2026)
B24: 14 | C24: ='P2.2 Timeline'!B24 | D24: ='P2.2 Timeline'!C24 | E24: ='P2.2 Timeline'!F24 | F24: ='P2.2 Timeline'!J24 | H24: R | L24: A | M24: S
B25: 15 | C25: ='P2.2 Timeline'!B25 | D25: ='P2.2 Timeline'!C25 | E25: ='P2.2 Timeline'!F25 | F25: ='P2.2 Timeline'!J25 | H25: S | U25: R | V25: R
B26: 16 | C26: ='P2.2 Timeline'!B26 | D26: ='P2.2 Timeline'!C26 | E26: ='P2.2 Timeline'!F26 | F26: ='P2.2 Timeline'!J26 | H26: R
B27: 17 | C27: ='P2.2 Timeline'!B27 | D27: ='P2.2 Timeline'!C27 | E27: ='P2.2 Timeline'!F27 | F27: ='P2.2 Timeline'!J27 | H27: R | V27: C
B28: 18 | C28: ='P2.2 Timeline'!B28 | D28: ='P2.2 Timeline'!C28 | E28: ='P2.2 Timeline'!F28 | F28: ='P2.2 Timeline'!J28
C29: Drafting, validation & governance papers (Jan–May 2027)
B30: 19 | C30: ='P2.2 Timeline'!B30 | D30: ='P2.2 Timeline'!C30 | E30: ='P2.2 Timeline'!F30 | F30: ='P2.2 Timeline'!J30 | H30: R
B31: 20 | C31: ='P2.2 Timeline'!B31 | D31: ='P2.2 Timeline'!C31 | E31: ='P2.2 Timeline'!F31 | F31: ='P2.2 Timeline'!J31 | H31: R | V31: C
B32: 21 | C32: ='P2.2 Timeline'!B32 | D32: ='P2.2 Timeline'!C32 | E32: ='P2.2 Timeline'!F32 | F32: ='P2.2 Timeline'!J32 | H32: R | L32: A
B33: 22 | C33: ='P2.2 Timeline'!B33 | D33: ='P2.2 Timeline'!C33 | E33: ='P2.2 Timeline'!F33 | F33: ='P2.2 Timeline'!J33 | H33: R | V33: S
B34: 23 | C34: ='P2.2 Timeline'!B34 | D34: ='P2.2 Timeline'!C34 | E34: ='P2.2 Timeline'!F34 | F34: ='P2.2 Timeline'!J34 | H34: S | J34: R | L34: A
B35: 24 | C35: ='P2.2 Timeline'!B35 | D35: ='P2.2 Timeline'!C35 | E35: ='P2.2 Timeline'!F35 | F35: ='P2.2 Timeline'!J35 | H35: R | L35: A
B36: 25 | C36: ='P2.2 Timeline'!B36 | D36: ='P2.2 Timeline'!C36 | E36: ='P2.2 Timeline'!F36 | F36: ='P2.2 Timeline'!J36 | H36: R | L36: A | N36: I
B37: 26 | C37: ='P2.2 Timeline'!B37 | D37: ='P2.2 Timeline'!C37 | E37: ='P2.2 Timeline'!F37 | F37: ='P2.2 Timeline'!J37 | H37: R | L37: A | N37: I
B38: 27 | C38: ='P2.2 Timeline'!B38 | D38: ='P2.2 Timeline'!C38 | E38: ='P2.2 Timeline'!F38 | F38: ='P2.2 Timeline'!J38 | H38: S | L38: R | N38: C
B39: 28 | C39: ='P2.2 Timeline'!B39 | D39: ='P2.2 Timeline'!C39 | E39: ='P2.2 Timeline'!F39 | F39: ='P2.2 Timeline'!J39 | H39: R | L39: A | O39: I
B40: 29 | C40: ='P2.2 Timeline'!B40 | D40: ='P2.2 Timeline'!C40 | E40: ='P2.2 Timeline'!F40 | F40: ='P2.2 Timeline'!J40 | H40: R | L40: A | O40: I
B41: 30 | C41: ='P2.2 Timeline'!B41 | D41: ='P2.2 Timeline'!C41 | E41: ='P2.2 Timeline'!F41 | F41: ='P2.2 Timeline'!J41 | H41: S | L41: R | O41: C
B42: 31 | C42: ='P2.2 Timeline'!B42 | D42: ='P2.2 Timeline'!C42 | E42: ='P2.2 Timeline'!F42 | F42: ='P2.2 Timeline'!J42 | H42: R | L42: A | P42: I
...

Sheet P3 To do – comms+web
B2: P3. Comms + web build to-do list
B4: Track comms, web build and design tasks. Priority: Low / Medium / High / Urgent.
B6: Report component or page | C6: Case study/content name | D6: Lead | E6: Priority level | F6: Agreed deadline | G6: Action needed | H6: Details | I6: Complete? (Y/N) | J6: Updates/blockers/FYI
B7: Web – whole report | C7: Year-specific report URL | D7: Comms/digital | E7: High | G7: Set up | H7: Use a year-specific URL (e.g. /sustainabilityreport/2026) and retain the central reports landing page (SR25 lesson).
B8: Web – whole report | C8: Analytics measures | D8: Comms/digital | E8: High | G8: Agree before launch | H8: Agree web sessions, users and views measures before launch so project close can report them.
B9: Web – whole report | C9: Accessibility & reviewer workflow testing | D9: Comms/digital | E9: High | G9: Test | H9: Navigation, links, mobile usability, accessibility, reviewer workflows – before governance approval.
B10: Report introduction | C10: Transition-year framing | D10: SST | E10: High | G10: Draft | H10: Explain former SP2030 vs Sustainability 2030 (launched ~20 Oct 2026).
B11: Whole report | C11: Whole-report review | D11: Strategic Comms | E11: High | G11: Schedule | H11: Schedule early enough for material changes.

Sheet P4 Content checklist
B2: P4. Content contributor checklist
B4: Stakeholder management for report content: review by contributors, images, credits and captions, post-launch follow-up.
B6: Report section | C6: Case study | D6: Activity areas | E6: Review required? (Y/N) | F6: Content contributors | G6: Project team liaison | H6: Sent for review (date) | I6: Changes required? (Y/N) | J6: SR26 draft updated? (Y/N) | K6: SR26 website updated? (Y/N) | L6: Images shared? (Y/N) | M6: Image URL | N6: Known image gap | O6: Credit noted? | P6: Caption text | Q6: Permission to publish confirmed? | R6: Post-launch: send to | S6: CC | T6: Sent (date) | U6: Complete? (Y/N)

Sheet P5 SR26 page index
B2: P5. SR26 page index (URLs)
B5: Ref | C5: Sustainability 2030 component | D5: Page name | E5: Story / case study | F5: SR26 link | G5: Page description | H5: Character count | I5: SR25 equivalent page
B6: FM01 | C6: N/A | D6: Landing page | H6: =LEN(G6)
B7: FM02 | C7: N/A | D7: Overview (transition year) | H7: =LEN(G7)
B8: FM03 | C8: N/A | D8: Our impact | H8: =LEN(G8)
B9: PA01 | C9: Education and research | D9: Exceptional education | H9: =LEN(G9)
B10: PA02 | C10: Education and research | D10: Transformational research | H10: =LEN(G10)
B11: PA03 | C11: Sustainability leadership | D11: Climate leadership | H11: =LEN(G11)
B12: PA04 | C12: Sustainability leadership | D12: Nature and biodiversity | H12: =LEN(G12)
B13: PA05 | C13: Sustainability leadership | D13: Responsible AI | H13: =LEN(G13)
B14: PA06 | C14: Resilient University | D14: Estate and infrastructure | H14: =LEN(G14)
B15: PA07 | C15: Resilient University | D15: Circular economy | H15: =LEN(G15)
B16: PA08 | C16: Resilient University | D16: Responsible procurement | H16: =LEN(G16)
B17: PA09 | C17: Resilient University | D17: Modern slavery and human rights | H17: =LEN(G17)
... B19: PA11 | C19: Enablers | D19: Enablers | H19: =LEN(G19)

Sheet Lists
B1: (not used – no target status rating in 2026) | C1: Data owner confirms | D1: Request status | E1: Y/N | K1: Report section
B2: Please select from dropdown | C2: Yes | D2: Not sent | E2: Yes | K2: Report introduction
C3: No | D3: Sent | E3: No | K3: Our impact
C4: Partially – see comments | D4: 1:1 meeting | E4: TBC | K4: Exceptional education
D5: Received | K5: Transformational research
D6: First review | K6: Climate leadership
D7: Follow-up | K7: Nature and biodiversity
D8: Complete | K8: Responsible AI
D9: Not required | K9: Estate and infrastructure
K10: Circular economy
K11: Responsible procurement
K12: Modern slavery and human rights
K13: Responsible investments
K14: Enablers
