Workbook

Sheet 0. Read me
A1: ↑ | B1: SR26 data collection master spreadsheet
B2: 2026 Sustainability Report – data collection master
B4: Purpose | C4: Central record of SR26 data requirements, owners, reporting requests, responses and evidence. Adapted from the 2025 end-year reporting master spreadsheet (V0.2) and the Sustainability 2030 updated targets (Qual and Quan worksheets).
B5: Status | C5: DRAFT v0.1 – pilot with 4 faculties (ABP, Arts, FBE, Science) and 5 central units (CI&S, CFOG, ESG, CIOG, MRE).
B6: Reporting approach | C6: Transition year: cover all of CY2026, distinguishing former Sustainability Plan 2030 activity from foundations and early actions after the Sustainability 2030 launch (~20 Oct 2026). Databook is the authoritative quantitative source. Target status (Met/Partially met/Not met) retained for now for internal management reporting – rating framework under review.
B7: Key dates (TBC) | C7: Requests issued: Nov–Dec 2026 | Highlighted stories due: Friday 4 December 2026 (TBC) | Reporting template due: Friday 15 January 2027 (TBC) | Support meetings: January 2027 | Sustainability Reporting Review Group: ~15 Feb 2027 | VCAG: 16 Feb & ~2 Mar 2027
B8: Tabs | C8: 1. Requirements matrix – every S2030 qualitative indicator, owner and request 2. Quant – Databook mapping – quantitative indicators to confirm with the Databook/central data owners 3. Stakeholder map & RASCI – SR25 → SR26 unit mapping and who is asked for what 4. Request tracker – sent/chased/received/confirmed status and response rate Faculties / CI&S / CFOG / ESG / CIOG / MRE – consolidated responses (copy in from returned request workbooks; same layout) Highlighted stories – consolidated optional stories and case-study shortlist A1. Data scoring – auto-pulls every unit's responses per indicator and scores target status (SR25 method) 0.5 Target Check – which units were asked about each indicator T2. Single target review – pick an indicator and see all units' responses and the scored status Request wording log – original S2030 wording vs tailored faculty request wording Evidence register – source, evidence, limitations and owner confirmation for every material claim Issues log – open questions, TBCs and decisions
B9: Refs | C9: Refs are new SR26 codes: priority-area code + target number + indicator letter (e.g. EE1(a) = Exceptional education, target 1, indicator a). 'Related SR25 ref' links to the closest SP2030 (2025) target where one exists.
B10: Regenerating | C10: Workbooks are generated by build.py in the repository. Edit the settings at the top (due dates, pilot faculties, unit mapping) and re-run to produce request workbooks for additional faculties/units.
B11: Request wording | C11: Faculty requests are rewritten in the SR25 style and point to each faculty's end-2025 response (see Request wording log). Central-unit requests use the S2030 'Qual' worksheet wording as-is.
B12: Formulas | C12: Responses must be pasted into the Faculties/central-unit tabs keeping the same rows – A1, 0.5 and T2 look them up by Ref. Do not insert rows inside a block; add new units by re-running build.py.

Sheet 1. Requirements matrix
A1: ↑ | B1: End-2026 target status assessment and reporting
B2: 1. Requirements matrix (qualitative)
B5: Ref | C5: Domain | D5: Priority area | E5: Target | F5: Indicator | G5: Reporting requirement (S2030 Qual sheet) | H5: Key stakeholders (S2030 sheet) | I5: SR26 request issued to | J5: Specific projects we are aware of (area & person) | K5: Internal vs External | L5: Flag for continuous improvement | M5: Notes | N5: Related SR25 ref | O5: Channel | P5: Owner confirmed?
B6: EE1(a) | C6: Education and research | D6: Exceptional education | E6: Provide our students with learning experiences that help them build the knowledge, skills and relationships to lead change for sustainable societies. | F6: Evidence of innovative approaches to sustainability teaching and learning | G6: Please describe any innovative approaches used within your Faculty/Portfolio to embed sustainability in teaching and learning. This could include examples of subjects, curriculum design, pedagogies, assessment approaches or learning resources. Please provide links or supporting evidence where available. | H6: Faculties, CI&S | I6: Faculties (pilot), CI&S | K6: Both | L6: No | N6: 4a(ii) | O6: Tailored request
B7: EE1(b) | C7: Education and research | D7: Exceptional education | E7: Provide our students with learning experiences that help them build the knowledge, skills and relationships to lead change for sustainable societies. | F7: Pilots of possible approaches for understanding and developing students’ sustainability self-efficacy | G7: Please describe any pilots or trials undertaken within your Faculty/Portfolio to understand or strengthen students’ sustainability self-efficacy. This could include the approach used, participating cohorts, what was assessed or learned, and any planned next steps. | H7: Faculties, CI&S | I7: Faculties (pilot), CI&S | J7: * Living Lab project (case study): Personalising Sustainability Pathways for students - Sustainability Strengths Compass. Project lead: Dianne Vella Brodrick. Funded partly by the Campus Living Lab Accelerator Program (CLLAP) (SST) | K7: Both | L7: No | O7: Tailored request
B8: EE1(c) | C8: Education and research | D8: Exceptional education | E8: Provide our students with learning experiences that help them build the knowledge, skills and relationships to lead change for sustainable societies. | F8: Evidence of sustainability focused experiential and co curricular learning (eg Wattle Fellowship; Melbourne Plus) | G8: Please provide examples of sustainability-focused experiential or co-curricular learning offered or supported by your Faculty/Portfolio (e.g. Wattle Fellowship, Melbourne Plus or similar), could include participation where available and a brief description of the learning experience and outcomes. | H8: Faculties, CI&S | I8: Faculties (pilot), CI&S | J8: * Wattle Fellowship (Linh Do); Wattle Fellowship could provide case studies and have an annual report. * Student and Scholarly Services (SASS - Melbourne Plus - Jess Trevitt) - how would we frame the ask differently for these data owners since we already know they offer experiential/co-curriculuar learning? SASS and Melbourne Plus can provide number of completions of students in the Sustainability Advocacy stream, and case studies. | K8: Both | L8: No | O8: Tailored request
B9: EE1(d) | C9: Education and research | D9: Exceptional education | E9: Provide our students with learning experiences that help them build the knowledge, skills and relationships to lead change for sustainable societies. | F9: Alumni profiles demonstrating how graduates contribute to sustainability through their careers or communities. | G9: Please provide examples or profiles of graduates or alumni from your Faculty who demonstrate how they apply sustainability knowledge, skills or capabilities through their careers, communities or other activities. Where available, include any evidence used by the Faculty to understand graduate outcomes related to sustainability. | H9: Faculties, CI&S | I9: Faculties (pilot), CI&S | K9: Both | L9: No | N9: 4b(i) | O9: Tailored request
B10: TR1(a) | C10: Education and research | D10: Transformational research | E10: Utilise the expertise of the University’s researchers through mutually beneficial partnerships to help address the University’s operational sustainability challenges. | F10: Expert-reviewed evidence of researchers contributing to operational sustainability priorities through partnerships, advisory input, living labs, applied projects or decision-support | G10: Please provide examples of researchers within your Faculty/Portfolio contributing to University operational sustainability priorities through partnerships, advisory input, living labs, applied projects or decision-support. Briefly describe the operational challenge, researcher contribution and resulting or expected outcome. | H10: Faculties, CI&S | I10: Faculties (pilot), CI&S | J10: MRE Campus Living Lab Accelerator Program (CLLAP) case studies (CI&S). Also Enterprise Services Group - Campus Operations and Delivery (COD) might have collaborations we're not aware of (e.g. Rachael Miller) | K10: Both | L10: No | N10: 2a | O10: Tailored request
B11: TR1(b) | C11: Education and research | D11: Transformational research | E11: Utilise the expertise of the University’s researchers through mutually beneficial partnerships to help address the University’s operational sustainability challenges. | F11: Evidence of institutional pathways that enable ongoing collaboration between academic and professional staff | G11: Please describe any pathways, mechanisms or processes within your Faculty/Portfolio that enable ongoing collaboration between academic and professional staff on operational sustainability challenges, could include formal programs, governance arrangements, funding mechanisms or coordination channels. | H11: Faculties | I11: Faculties (pilot) | J11: MRE | K11: Both | L11: No | O11: Tailored request
B12: TR1(c) | C12: Education and research | D12: Transformational research | E12: Utilise the expertise of the University’s researchers through mutually beneficial partnerships to help address the University’s operational sustainability challenges. | F12: Expert assessment of the quality, relevance and continuity of these collaborations | G12: Please provide an assessment of the quality, relevance and continuity of sustainability-related collaborations involving your Faculty/Portfolio, could include evidence of whether collaborations are sustained, useful to operational priorities and producing relevant outcomes. | H12: Faculties | I12: Faculties (pilot) | J12: MRE | K12: Both | L12: No | O12: Tailored request
B13: TR1(d) | C13: Education and research | D13: Transformational research | E13: Utilise the expertise of the University’s researchers through mutually beneficial partnerships to help address the University’s operational sustainability challenges. | F13: Periodic feedback from participants on the effectiveness and mutual benefit of collaboration mechanisms. | G13: Please provide any participant feedback or other evidence from your Faculty/Portfolio on the effectiveness and mutual benefit of collaboration mechanisms between researchers and operational teams, could include key findings and any improvements identified. | H13: Faculties | I13: Faculties (pilot) | J13: MRE | K13: Both | L13: No | O13: Tailored request
B14: TR2(a) | C14: Education and research | D14: Transformational research | E14: Deliver high-quality research and partnerships that contribute to sustainability outcomes and demonstrable societal benefit. | F14: Evidence of sustainability-related research impact across diverse pathways, could include policy, industry, community, practice, cultural and institutional outcomes | G14: Please provide examples of sustainability-related research impact from your Faculty/Portfolio across policy, industry, community, practice, cultural or institutional pathways. For key examples, briefly describe the research contribution, partner/user and resulting outcome or influence. | H14: Faculties | I14: Faculties (pilot) | J14: Melbourne Research and Enterprise (Nishi Raja-Stranger and Ivan Marusic) Strategic Communications - Research lead will be able to identify examples of impactful sustainability-related research; also Pursuit (may be via Strat Comms too) Melbourne Climate Futures (Ben Neville, Beth Barber, Belle Workman) - MCF produce an annual impact report we could refer to. Melbourne Biodiversity Insitute (Brendan Wintle, Alanta Colley, Rachel Morgain) Possibly Melbourne Energy Institute. MDHS Climate CATCH Lab and other specific research centres could be approached and asked about their impact, or we could flag specific research centres in faculty requests. | K14: Both | L14: No | N14: 5b(i) | O14: Tailored request
B15: TR2(b) | C15: Education and research | D15: Transformational research | E15: Deliver high-quality research and partnerships that contribute to sustainability outcomes and demonstrable societal benefit. | F15: Documented progress of relevant strategic initiatives, including Impact Accelerators | G15: Please provide case studies demonstrating how University research has contributed to meaningful sustainability outcomes. For each case, briefly describe the research, stakeholders involved, pathway to impact and evidence of the resulting sustainability outcome. | I15: TBC – no owner identified | K15: Both | L15: No | M15: documented progress imply that university have good governance over the management of initiatives and therefore could provide percentage of milestone completion | O15: Databook / central data owner
B16: TR2(c) | C16: Education and research | D16: Transformational research | E16: Deliver high-quality research and partnerships that contribute to sustainability outcomes and demonstrable societal benefit. | F16: Expert-reviewed summary of sustainability-related research outputs, outcomes and influence using available institutional evidence sources | G16: currently mapped to the SDGs using SciVal | H16: MRE | I16: MRE | K16: Both | L16: No | O16: Tailored request
B17: TR2(d) | C17: Education and research | D17: Transformational research | E17: Deliver high-quality research and partnerships that contribute to sustainability outcomes and demonstrable societal benefit. | F17: Case-based evidence demonstrating how research has contributed to meaningful sustainability outcomes. | G17: Please provide case studies from your Faculty/Portfolio demonstrating how research has contributed to meaningful sustainability outcomes. Briefly describe the research, stakeholders involved, pathway to impact and evidence of the resulting sustainability outcome. | H17: Faculties, CI&S | I17: Faculties (pilot), CI&S | J17: Strategic Communications - Research lead will be able to identify examples of impactful sustainability-related research; also Pursuit (may be via Strat Comms too) Melbourne Climate Futures (Ben Neville, Beth Barber, Belle Workman) Melbourne Biodiversity Insitute (Brendan Wintle, Alanta Colley, Rachel Morgain) Possibly Melbourne Energy Institute. | K17: Both | L17: No | N17: 5b(i) | O17: Tailored request
B18: TR3(a) | C18: Education and research | D18: Transformational research | E18: Embed sustainability within research systems, processes, capability and culture, so research is conducted responsibly, efficiently and with reduced environmental impact. | F18: Evidence that sustainability considerations are integrated into relevant research systems, planning processes, guidance, training, induction or support services | G18: Please describe how sustainability considerations are integrated into research systems, planning processes, guidance, training, induction or support services within your Faculty/Portfolio, could include examples of any new or improved processes. | H18: Faculties, CI&S | I18: Faculties (pilot), CI&S | K18: Both | L18: No | N18: 5c(ii) | O18: Tailored request
B19: TR3(b) | C19: Education and research | D19: Transformational research | E19: Embed sustainability within research systems, processes, capability and culture, so research is conducted responsibly, efficiently and with reduced environmental impact. | F19: Demonstrated examples of more sustainable research practices in laboratories, fieldwork, procurement, travel or infrastructure use | G19: Please describe any efforts within your Faculty/Portfolio to make research practices more sustainable, could include examples from laboratories, fieldwork, procurement, research travel or infrastructure use. Where available, provide evidence of uptake, resource savings, emissions reductions or other outcomes. | H19: Faculties, CI&S, CFOG | I19: Faculties (pilot), CI&S, CFOG | K19: Both | L19: No | N19: 5c(ii) | O19: Tailored request
B20: TR3(c) | C20: Education and research | D20: Transformational research | E20: Embed sustainability within research systems, processes, capability and culture, so research is conducted responsibly, efficiently and with reduced environmental impact. | F20: Evidence of progress in sustainability-related research culture, capability and awareness, informed by periodic staff and graduate researcher surveys | G20: Please provide evidence of progress in sustainability-related research culture, capability and awareness within your Faculty/Portfolio. This could include relevant staff and/or graduate researcher survey findings, participation in capability-building activities, or other indicators of change over time. | H20: Faculties | I20: Faculties (pilot) | J20: Melbourne Research and Enterprise (Nishi Raja-Stranger; Ivan Marusic) - MRE will be a key reporter for all research targets. | K20: Both | L20: No | O20: Tailored request
B21: TR3(d) | C21: Education and research | D21: Transformational research | E21: Embed sustainability within research systems, processes, capability and culture, so research is conducted responsibly, efficiently and with reduced environmental impact. | F21: Expert assessment of progress in embedding sustainable research practices across the institution. | G21: Faculty/Portfolio’s assessment of progress in embedding sustainable research practices, highlighting areas of strong progress, remaining gaps and priority actions for further improvement. | H21: Faculties | I21: Faculties (pilot) | K21: Both | L21: No | O21: Tailored request
B22: CL1(a) | C22: Sustainability leadership | D22: Climate leadership | E22: Achieve net zero emissions by 2050: Interim target Reduce emissions by 20% across all emissions scopes by CY2030 on the CY2023 re-baseline including: • Scopes 1 and 2: 66% reduction • Scope 3: 12% reduction. Long-term target Reduce emissions by 90% across all emissions scopes by CY2050 on the CY2023 re-baseline and invest in carbon removal credits for residual emissions from hard-to-abate sources (up to 10%). | F22: Annual Greenhouse Gas Inventory (including emissions scopes 1, 2 and 3) demonstrates carbon emission reductions, including maintaining procurement of 100% renewable electricity for all scope 2 sources[1] | G22: Total scope 1,2 and 3 emissions (tCO2-e); emissions by scope; % reduction from previous baseline; % renewable electircity produced | I22: TBC – no owner identified | K22: Both | L22: No | M22: Directly measures progress against the stated emission reduction targets and allows annual comparison against the baseline and trajectory | O22: Databook / central data owner
B23: CL1(b) | C23: Sustainability leadership | D23: Climate leadership | E23: Achieve net zero emissions by 2050: Interim target Reduce emissions by 20% across all emissions scopes by CY2030 on the CY2023 re-baseline including: • Scopes 1 and 2: 66% reduction • Scope 3: 12% reduction. Long-term target Reduce emissions by 90% across all emissions scopes by CY2050 on the CY2023 re-baseline and invest in carbon removal credits for residual emissions from hard-to-abate sources (up to 10%). | F23: Development of Greenhouse Gas intensity metrics | G23: Greenhouse gas emissions by FTE, EFTSL, and Gross floor area (https://www.unimelb.edu.au/sustainabilityreport/2025/data-tables#GHGe-scope) | I23: TBC – no owner identified | K23: Both | L23: Yes | M23: Quantiative indicator | O23: Databook / central data owner
B24: CL1(c) | C24: Sustainability leadership | D24: Climate leadership | E24: Achieve net zero emissions by 2050: Interim target Reduce emissions by 20% across all emissions scopes by CY2030 on the CY2023 re-baseline including: • Scopes 1 and 2: 66% reduction • Scope 3: 12% reduction. Long-term target Reduce emissions by 90% across all emissions scopes by CY2050 on the CY2023 re-baseline and invest in carbon removal credits for residual emissions from hard-to-abate sources (up to 10%). | F24: Review of Climate Leadership targets by 2030.[2] | H24: CI&S | I24: CI&S | K24: Both | L24: Yes | M24: Need to review again on 2030. The climate target itself is still two months old | O24: Tailored request
B25: CL2(a) | C25: Sustainability leadership | D25: Climate leadership | E25: Develop understanding of our research and education programs that contribute to accelerating global decarbonisation and our own climate transition. | F25: By 2028, develop and document institutional mapping of research and education activities that are designed to contribute to global decarbonisation | G25: Please list and describe examples of communications from your Faculty/Portfolio that demonstrate climate action, research and learning and aim to inform policy, sector or community decarbonisation efforts. Could include links, intended audiences and any available evidence of reach or influence. | H25: Faculties, CI&S | I25: Faculties (pilot), CI&S | K25: Both | L25: No | O25: Tailored request
B26: CL2(b) | C26: Sustainability leadership | D26: Climate leadership | E26: Develop understanding of our research and education programs that contribute to accelerating global decarbonisation and our own climate transition. | F26: Prioritised pipeline of decarbonisation focused research and education opportunities aligned with University emissions reduction priorities from 2028 | G26: Number of pipelined projects or research transitioned from opportunity to active per year | I26: TBC – no owner identified | K26: Both | L26: No | M26: Pipeline can be quantitatively tracked through volume and progression, but since the target is prioritised pipeline, showing number of sucessful pipeline transitioned is more desirable | O26: Databook / central data owner
B27: CL2(c) | C27: Sustainability leadership | D27: Climate leadership | E27: Develop understanding of our research and education programs that contribute to accelerating global decarbonisation and our own climate transition. | F27: Ongoing communications that evidence the University’s climate action, research and learning to inform policy, sector and community decarbonisation efforts. | G27: List and describe communications from the faculty in terms of climate action, research and learning to inform policy, sector and community decarbonisation efforts | H27: Faculties, | I27: Faculties (pilot) | K27: Both | L27: No | O27: Tailored request
B28: CL3(a) | C28: Sustainability leadership | D28: Climate leadership | E28: Reach and maintain high levels of climate-change resilience maturity | F28: Maturity assessment of the University’s preparedness for climate-related impacts and capability to respond, assessed across relevant organisational functions: o Governance and strategy o Health and safety o Business continuity o Emergency management and critical incidence management o Estate and buildings o Water management o Financial planning and reporting. | G28: Provide update of University maturity assesment. Include maturity ratings, key gaps and priority improvement actions.when available | H28: CI&S | I28: CI&S | K28: Both | L28: No | M28: Could check with Gerard. Gerard is the one who manage this indicator | O28: Tailored request
B29: NB1(a) | C29: Sustainability leadership | D29: Nature and biodiversity | E29: Achieve an increase of biodiversity relative to defined baseline years for each campus. | F29: Monitoring of biodiversity metrics from the Biodiversity Baseline Data Project | G29: 7 diversity metrics from https://sustainablecampus.unimelb.edu.au/biodiversity/biodiversity-baseline-data-project#main-content | I29: TBC – no owner identified | K29: Both | L29: No | M29: Quantitative indicator | O29: Databook / central data owner
B30: NB1(b) | C30: Sustainability leadership | D30: Nature and biodiversity | E30: Achieve an increase of biodiversity relative to defined baseline years for each campus. | F30: Size, health and diversity of remnant vegetation at the Dookie and Creswick campuses | H30: Rachel | I30: ESG | K30: Internal | L30: No | M30: Havent been previously disclose publicly | O30: Tailored request
B31: NB1(c) | C31: Sustainability leadership | D31: Nature and biodiversity | E31: Achieve an increase of biodiversity relative to defined baseline years for each campus. | F31: Defined quality measurement framework | H31: ESG | I31: ESG | K31: Both | L31: No | M31: Follow up with Rachel | O31: Tailored request
B32: NB1(d) | C32: Sustainability leadership | D32: Nature and biodiversity | E32: Achieve an increase of biodiversity relative to defined baseline years for each campus. | F32: Defined and quantified campus connectivity | G32: Please provide the current definition and quantified assessment of campus ecological connectivity, could include the methodology used, campuses covered, baseline or benchmark values, and any material change over the reporting period. | H32: ESG | I32: ESG | K32: Both | L32: No | O32: Tailored request
B33: NB2(a) | C33: Sustainability leadership | D33: Nature and biodiversity | E33: Improve our understanding of our supply chain impacts on nature. | F33: Documented baseline nature footprint analysis | G33: Impact Encore Measurement | H33: MBI | I33: MRE | K33: Both | L33: No | O33: Tailored request
B34: NB2(b) | C34: Sustainability leadership | D34: Nature and biodiversity | E34: Improve our understanding of our supply chain impacts on nature. | F34: Evidence of established framework to monitor and track supply-chain nature impacts over time | G34: Please describe the framework established to monitor and track supply-chain impacts on nature over time, could include metrics, data sources, governance/ownership, reporting frequency and current implementation status. | H34: ESG | I34: ESG | J34: Melbourne Biodiversity Institute (MBI) - Brendan Wintle and August Wylynko | K34: Both | L34: No | O34: Tailored request
B35: NB2(c) | C35: Sustainability leadership | D35: Nature and biodiversity | E35: Improve our understanding of our supply chain impacts on nature. | F35: Evidence of prioritised high risk procurement categories or suppliers for nature impact management | G35: Please provide the prioritised high-risk procurement categories and/or suppliers identified for nature-impact management, could include the basis for prioritisation and any risk-management, engagement or mitigation actions undertaken or planned. | H35: ESG, CFOG | I35: CFOG, ESG | J35: MBI | K35: Both | L35: No | O35: Tailored request
B36: AI1(a) | C36: Sustainability leadership | D36: Responsible AI | E36: Improve understanding of our sustainability-related risks and opportunities of AI technologies by 2028. | F36: Established measurement of estimated operational impacts and opportunities (eg operational impacts could include energy, water, emissions and intensity measures) | H36: CI&S, CIOG | I36: CI&S, CIOG | K36: Both | L36: Yes | M36: Rose & Sally currently actively managing this target and indicator. High level overview on 2026, will work on the detailed measurement next year | O36: Tailored request
B37: AI1(b) | C37: Sustainability leadership | D37: Responsible AI | E37: Improve understanding of our sustainability-related risks and opportunities of AI technologies by 2028. | F37: Case studies of sustainability and AI-related education, research and collaboration activities. | G37: Please provide case studies from your Faculty/Portfolio of sustainability and AI-related education, research or collaboration activities, describing the activity, participants or partners, sustainability issue addressed and key outcomes or lessons. | H37: CI&S, CIOG | I37: CI&S, CIOG | J37: AI Steering Committee - developing AI roadmap, which includes responsible AI as a key pillar. | K37: Both | L37: No | O37: Tailored request
B38: EI1(a) | C38: Resilient University | D38: Estate and infrastructure | E38: Integrate environmental sustainability in the way that the University achieves strategic and operational objectives for our estate and infrastructure. | F38: Evidence of increased maturity of estate and infrastructure planning, development and operations to support the other priority areas in Sustainability 2030 | G38: Case study evidence of increased sustainability maturity in estate and infrastructure planning, development and operations, could include examples of changes to standards, processes, governance, decision-making or project requirements that support Sustainability 2030 priority areas. | H38: CI&S | I38: CI&S | J38: CI&S - Estate Planning and Development teams | K38: Both | L38: No | M38: Facilitated by Gerard | O38: Tailored request
B39: EI1(b) | C39: Resilient University | D39: Estate and infrastructure | E39: Integrate environmental sustainability in the way that the University achieves strategic and operational objectives for our estate and infrastructure. | F39: Estimated sustainability impacts of the University’s estate and infrastructure capital plan to inform progress towards emissions reduction targets and other priority areas (to the extent enabled by available information) | G39: Please provide any available information on sustainability impacts associated with estate and infrastructure projects or capital works relevant to your Faculty/Portfolio. This could include impacts related to emissions and other Sustainability 2030 priority areas. | H39: CI&S | I39: CI&S | J39: CI&S - Estate Planning and Development teams | K39: Both | L39: No | O39: Tailored request
B40: EI1(c) | C40: Resilient University | D40: Estate and infrastructure | E40: Integrate environmental sustainability in the way that the University achieves strategic and operational objectives for our estate and infrastructure. | F40: Reporting on relevant activities and impacts for the University’s major estate and infrastructure projects and programs aligned with the other priority areas in Sustainability 2030 | G40: Please provide an update on sustainability-related activities and impacts for major estate and infrastructure projects or programs relevant to your Faculty/Portfolio. This could include key initiatives, relevant performance measures and alignment with Sustainability 2030 priority areas. | H40: CI&S | I40: CI&S | J40: CI&S - Estate Planning and Development teams | K40: Both | L40: No | O40: Tailored request
B41: EI1(d) | C41: Resilient University | D41: Estate and infrastructure | E41: Integrate environmental sustainability in the way that the University achieves strategic and operational objectives for our estate and infrastructure. | F41: Evidence of understanding and integration of Indigenous approaches to sustainability in estate planning and development programs and projects. | G41: Please provide examples showing how Indigenous approaches, knowledges or perspectives on sustainability have informed estate planning, development programs or projects relevant to your Faculty/Portfolio. This could include how Indigenous stakeholders were engaged and what changed as a result. | H41: CI&S | I41: CI&S | J41: CI&S - Estate Planning and Development teams | K41: Both | L41: No | O41: Tailored request
B42: CE1(a) | C42: Resilient University | D42: Circular economy | E42: Reduce waste to landfill by 10% by CY2030 on the CY2025 baseline. | F42: Comparison of year-to-year tonnes of waste (absolute). | G42: tonnes of waste; % change against previous baseline | I42: TBC – no owner identified | K42: Both | L42: No | M42: Quantitative indicator | O42: Databook / central data owner
...

Sheet 2. Quant – Databook mapping
A1: ↑ | B1: End-2026 target status assessment and reporting
B2: 2. Quantitative indicators – Databook mapping
B3: Databook is the authoritative quantitative source – confirm coverage first and only request data separately where an indicator is not covered. Per the SR26 approach: map Sep–Oct; confirm provisional data in January; finalise by February.
B5: Ref | C5: Priority area | D5: Indicator | E5: Quant? (Y/M) | F5: Suggested metric | G5: Key person to follow up | H5: Internal vs External | I5: Analysis notes | J5: Covered by Databook? | K5: Definition | L5: Reporting boundary | M5: Period | N5: Source system | O5: End-2026 figure | P5: Quality note / limitations | Q5: Data owner | R5: Owner confirmed? | S5: Confirmation date
B6: EE1(c) | C6: Exceptional education | D6: Evidence of sustainability focused experiential and co curricular learning (eg Wattle Fellowship; Melbourne Plus) | E6: M | F6: Number of experiential learning projects; number of participating students | H6: Both | I6: Quantitative metrics could help shows the reach of projects, especially the student metrics
B7: EE1(d) | C7: Exceptional education | D7: Alumni profiles demonstrating how graduates contribute to sustainability through their careers or communities. | E7: M | F7: Number of alumni that contribute to sustainability; % profiles demonstrating sustainability contribution; insights form different industries that influenced by alumni | H7: Both | I7: Number and percentage of profiles could be underwhelming, but it helps to track the trajectory. I supposed qualitative case of selected profiles would still be the primary metrics.
B8: TR2(b) | C8: Transformational research | D8: Documented progress of relevant strategic initiatives, including Impact Accelerators | E8: Y | F8: Percentage of milestone completion rate to the set annual target of strategic initiatives; number of initiatives on track; number of initiatives delivered | H8: Both | I8: documented progress imply that university have good governance over the management of initiatives and therefore could provide percentage of milestone completion
B9: TR2(c) | C9: Transformational research | D9: Expert-reviewed summary of sustainability-related research outputs, outcomes and influence using available institutional evidence sources | E9: Y | F9: currently mapped to the SDGs using SciVal, old metrics explorer (publication mapped to SDG whether they mentioned in mews, media, policy,etc), | G9: MRE, Gerard | H9: Both | I9: To discuss contatct of researchers with Gerad
B10: TR3(b) | C10: Transformational research | D10: Demonstrated examples of more sustainable research practices in laboratories, fieldwork, procurement, travel or infrastructure use | E10: M | F10: Number of laboratories achieving green lab certification; number of new sustainable activity; number of sustainability fieldwork | G10: MRE, Gerard | H10: Both | I10: To discuss contatct of researchers with Gerad
B11: CL1(a) | C11: Climate leadership | D11: Annual Greenhouse Gas Inventory (including emissions scopes 1, 2 and 3) demonstrates carbon emission reductions, including maintaining procurement of 100% renewable electricity for all scope 2 sources[1] | E11: Y | F11: Total scope 1,2 and 3 emissions (tCO2-e); emissions by scope; % reduction from previous baseline; % renewable electircity produced | H11: Both | I11: Directly measures progress against the stated emission reduction targets and allows annual comparison against the baseline and trajectory
B12: CL1(b) | C12: Climate leadership | D12: Development of Greenhouse Gas intensity metrics | E12: Y | F12: Greenhouse gas emissions by FTE, EFTSL, and Gross floor area (https://www.unimelb.edu.au/sustainabilityreport/2025/data-tables#GHGe-scope) | H12: Both | I12: Quantiative indicator
B13: CL1(c) | C13: Climate leadership | D13: Review of Climate Leadership targets by 2030.[2] | E13: M | H13: Both | I13: Will be re-assesed in 2030
B14: CL2(a) | C14: Climate leadership | D14: By 2028, develop and document institutional mapping of research and education activities that are designed to contribute to global decarbonisation | E14: M | F14: Number of relevant research projects/programs mapped; number of relevant subjects mapped | H14: Both | I14: Although the core commitment is completion of the mapping (binary), quantitative measures still useful to show its coverage and comprehensiveness
B15: CL2(b) | C15: Climate leadership | D15: Prioritised pipeline of decarbonisation focused research and education opportunities aligned with University emissions reduction priorities from 2028 | E15: Y | F15: Number of pipelined projects or research transitioned from opportunity to active per year | H15: Both | I15: Pipeline can be quantitatively tracked through volume and progression, but since the target is prioritised pipeline, showing number of sucessful pipeline transitioned is more desirable
B16: CL2(c) | C16: Climate leadership | D16: Ongoing communications that evidence the University’s climate action, research and learning to inform policy, sector and community decarbonisation efforts. | E16: M | F16: Annual count of published documents, policy briefs, or public engagement events; number of policy/sector engagement; # views of communication material | G16: MCF; MEI | H16: Both | I16: Brainstorm with MCF and MEI
B17: CL3(a) | C17: Climate leadership | D17: Maturity assessment of the University’s preparedness for climate-related impacts and capability to respond, assessed across relevant organisational functions: o Governance and strategy o Health and safety o Business continuity o Emergency management and critical incidence management o Estate and buildings o Water management o Financial planning and reporting. | E17: M | F17: Maturity score by function; overall/average maturity score; % functions raching target maturity level | H17: Both | I17: If defined maturity is already available, then it is desirable to have quantitative metrics, especially since the target mentioned maturity assesment
B18: NB1(a) | C18: Nature and biodiversity | D18: Monitoring of biodiversity metrics from the Biodiversity Baseline Data Project | E18: Y | F18: 7 diversity metrics from https://sustainablecampus.unimelb.edu.au/biodiversity/biodiversity-baseline-data-project#main-content | H18: Both | I18: Quantitative indicator
B19: NB1(b) | C19: Nature and biodiversity | D19: Size, health and diversity of remnant vegetation at the Dookie and Creswick campuses | E19: Y | G19: Rachel | H19: Both
B20: NB1(c) | C20: Nature and biodiversity | D20: Defined quality measurement framework | E20: M | G20: Rachel | H20: Both
B21: NB1(d) | C21: Nature and biodiversity | D21: Defined and quantified campus connectivity | E21: M | G21: Rachel | H21: Both
B22: NB2(a) | C22: Nature and biodiversity | D22: Documented baseline nature footprint analysis | E22: Y | F22: Impact Encore Measurement | G22: August, MBI | H22: Both
B23: AI1(a) | C23: Responsible AI | D23: Established measurement of estimated operational impacts and opportunities (eg operational impacts including energy, water, emissions and intensity measures) | E23: M | F23: Pending denominator | H23: Both | I23: Will start with qual on 2026, then move on to quan
B24: EI1(a) | C24: Estate and infrastructure | D24: Evidence of increased maturity of estate and infrastructure planning, development and operations to support the other priority areas in Sustainability 2030 | E24: M | F24: qual, climate resilience?, | G24: Gerard | H24: Both
B25: EI1(b) | C25: Estate and infrastructure | D25: Estimated sustainability impacts of the University’s estate and infrastructure capital plan to inform progress towards emissions reduction targets and other priority areas (to the extent enabled by available information) | E25: M | F25: Forecast operational emission (tCO2-e); expected energy consumptions/savings; expected water impact; expected waste material impact; potential biodiversity impact | G25: Gerard | H25: Both | I25: Quantitative estimates/forecast (impact estimation) allow better planning and management to achieve the overall sustainability plan and targets (follow up with Gerard)
B26: EI1(c) | C26: Estate and infrastructure | D26: Reporting on relevant activities and impacts for the University’s major estate and infrastructure projects and programs aligned with the other priority areas in Sustainability 2030 | E26: M | F26: case by case | G26: Gerard | H26: Both
B27: CE1(a) | C27: Circular economy | D27: Comparison of year-to-year tonnes of waste (absolute). | E27: Y | F27: tonnes of waste; % change against previous baseline | H27: Both | I27: Quantitative indicator
B28: CE2(a) | C28: Circular economy | D28: Comparison of year-to-year tonnes of recyclables (absolute). | E28: Y | F28: waste diversion rate; tonnes diverted from landfill; % change against previous baseline | H28: Both | I28: Quantitative indicator
B29: RP1(a) | C29: Responsible procurement | D29: Case studies of maturity improvement related to responsible procurement process and systems. | E29: Y | F29: Maturity score if framework established; % procurement staff trained | H29: Both | I29: Quantitative metrics could support qualitative case studies to demonstrate system/process improvements
B30: RP2(a) | C30: Responsible procurement | D30: Percentage of Indigenous spend of total addressable procurement spend | E30: Y | F30: Percentage of Indigenous spend of total addressable procurement spend | H30: Both | I30: Quantitative indicator
B31: RP2(b) | C31: Responsible procurement | D31: Percentage of social spend of total addressable procurement spend. | E31: Y | F31: Percentage of social spend of total addressable procurement spend. | H31: Both | I31: Quantitative indicator
B32: RI1(a) | C32: Responsible investments | D32: Annual monitoring and reporting on the investment portfolio’s net zero transition progress, including tracking the percentage of assets under management (AUM) managed by investment managers aligned with (or committed to) net zero by 2050 | E32: Y | F32: Percentage of AUM managed by investment managers aligned with net zero by 2050 | H32: Both | I32: Quantitative indicator
B33: RI1(b) | C33: Responsible investments | D33: Continuous improvement of the reporting of the University’s sustainability-related investment profile metrics, including investment in climate mitigation and transition solutions, and compliance with related obligations (eg UNPRI). | E33: M | F33: $ and % AUM invested in climate/transition solution | H33: Both | I33: "Continuous improvement" wording makes it desirable to have a quantitative comparison metrics. However i also acknowledge that this target is mainly a qualitative target
B34: EN1(b) | C34: Enablers | D34: Living laboratories enabling applied learning, research and operational sustainability outcomes | E34: M | F34: Number of projects funded; $ project funding | H34: Both | I34: Qualitative case evidence is better to articulate the impact of living laboratories in learning, research, and operational sustainability outcomes

Sheet 3. Stakeholder map & RASCI
A1: ↑ | B1: End-2026 target status assessment and reporting
B2: 3. Stakeholder map & RASCI
B4: SR26 unit | C4: SR26 full name | D4: SR25 equivalent (2025 master) | E4: Section / team | F4: Key contact | G4: Status / notes
B5: Faculty | C5: Faculty of Architecture, Building and Planning | D5: Faculties tab – ABP | E5: Associate Dean Sustainability / faculty sustainability lead | F5: TBC | G5: Pilot faculty
B6: Faculty | C6: Faculty of Arts | D6: Faculties tab – ARTS | E6: Associate Dean Sustainability / faculty sustainability lead | F6: TBC | G6: Pilot faculty
B7: Faculty | C7: Faculty of Business and Economics | D7: Faculties tab – FBE | E7: Associate Dean Sustainability / faculty sustainability lead | F7: TBC | G7: Pilot faculty
B8: Faculty | C8: Faculty of Science | D8: Faculties tab – SCI | E8: Associate Dean Sustainability / faculty sustainability lead | F8: TBC | G8: Pilot faculty
B9: CI&S | C9: Commercial, Infrastructure & Sustainability (CI&S) | D9: Corporate Development (CD Development & Estate Planning teams; CD Sustainability Strategy) | E9: CI&S – Estate Planning & Development (TBC: confirm with Gerard) | F9: TBC
B10: CI&S | C10: Commercial, Infrastructure & Sustainability (CI&S) | D10: Corporate Development (CD Development & Estate Planning teams; CD Sustainability Strategy) | E10: CI&S – Sustainability Strategy (incl. CLLAP) | F10: TBC
B11: CFOG | C11: Chief Finance Officer Group (CFOG) | D11: CFOG (Procurement; Accounting; Treasury & Investments; Enterprise Portfolio & Investments) | E11: CFOG – Procurement | F11: TBC
B12: CFOG | C12: Chief Finance Officer Group (CFOG) | D12: CFOG (Procurement; Accounting; Treasury & Investments; Enterprise Portfolio & Investments) | E12: CFOG – Treasury & Investments | F12: TBC
B13: ESG | C13: Enterprise Services Group (ESG) | D13: Business Services – Sustainability Delivery (nature & biodiversity, waste & circular economy, part of quant. climate leadership) | E13: ESG – Campus Operations & Sustainability Delivery | F13: TBC
B14: CIOG | C14: Chief Information Officer Group (CIOG) | D14: Business Services (AI – not requested in SR25) | E14: CIOG – Responsible AI & digital | F14: TBC
B15: MRE | C15: Melbourne Research and Enterprise (MRE) | D15: Chancellery Research and Enterprise | E15: MRE – Research (incl. MBI – TBC) | F15: TBC
B16: Chancellery | C16: Advancement, Communications & Marketing; Global, Culture & Engagement; Education (incl. SASS); Indigenous | D16: Chancellery tab | E16: — | F16: TBC | G16: No SR26 qualitative indicator currently names these units. SASS (Melbourne Plus) referenced for EE1(c). Confirm whether requests are needed.
B17: Legal & Risk | C17: Legal and Risk | D17: Legal and Risk tab | E17: — | F17: TBC | G17: No SR26 indicator currently assigned – may be relevant to climate resilience maturity (CL3(a)). TBC.
B18: TBC | C18: CGOP / CDEP / CDSS | D18: Not in SR25 master | E18: — | F18: TBC | G18: Structure changes TBC – confirm before requests are issued.
B20: RASCI – who receives a request for each indicator (R = Responsible to report; TBC = to confirm)
B21: Ref | C21: Priority area | D21: Indicator | E21: ABP | F21: ARTS | G21: FBE | H21: SCI | I21: CI&S | J21: CFOG | K21: ESG | L21: CIOG | M21: MRE
B22: EE1(a) | C22: Exceptional education | D22: Evidence of innovative approaches to sustainability teaching and learning | E22: R | F22: R | G22: R | H22: R | I22: R
B23: EE1(b) | C23: Exceptional education | D23: Pilots of possible approaches for understanding and developing students’ sustainability self-efficacy | E23: R | F23: R | G23: R | H23: R | I23: R
B24: EE1(c) | C24: Exceptional education | D24: Evidence of sustainability focused experiential and co curricular learning (eg Wattle Fellowship; Melbourne Plus) | E24: R | F24: R | G24: R | H24: R | I24: R
B25: EE1(d) | C25: Exceptional education | D25: Alumni profiles demonstrating how graduates contribute to sustainability through their careers or communities. | E25: R | F25: R | G25: R | H25: R | I25: R
B26: TR1(a) | C26: Transformational research | D26: Expert-reviewed evidence of researchers contributing to operational sustainability priorities through partnerships, advisory input, living labs, applied projects or decision-support | E26: R | F26: R | G26: R | H26: R | I26: R
B27: TR1(b) | C27: Transformational research | D27: Evidence of institutional pathways that enable ongoing collaboration between academic and professional staff | E27: R | F27: R | G27: R | H27: R
B28: TR1(c) | C28: Transformational research | D28: Expert assessment of the quality, relevance and continuity of these collaborations | E28: R | F28: R | G28: R | H28: R
B29: TR1(d) | C29: Transformational research | D29: Periodic feedback from participants on the effectiveness and mutual benefit of collaboration mechanisms. | E29: R | F29: R | G29: R | H29: R
B30: TR2(a) | C30: Transformational research | D30: Evidence of sustainability-related research impact across diverse pathways, could include policy, industry, community, practice, cultural and institutional outcomes | E30: R | F30: R | G30: R | H30: R
B31: TR2(b) | C31: Transformational research | D31: Documented progress of relevant strategic initiatives, including Impact Accelerators
B32: TR2(c) | C32: Transformational research | D32: Expert-reviewed summary of sustainability-related research outputs, outcomes and influence using available institutional evidence sources | M32: R
B33: TR2(d) | C33: Transformational research | D33: Case-based evidence demonstrating how research has contributed to meaningful sustainability outcomes. | E33: R | F33: R | G33: R | H33: R | I33: R
B34: TR3(a) | C34: Transformational research | D34: Evidence that sustainability considerations are integrated into relevant research systems, planning processes, guidance, training, induction or support services | E34: R | F34: R | G34: R | H34: R | I34: R
B35: TR3(b) | C35: Transformational research | D35: Demonstrated examples of more sustainable research practices in laboratories, fieldwork, procurement, travel or infrastructure use | E35: R | F35: R | G35: R | H35: R | I35: R | J35: R
B36: TR3(c) | C36: Transformational research | D36: Evidence of progress in sustainability-related research culture, capability and awareness, informed by periodic staff and graduate researcher surveys | E36: R | F36: R | G36: R | H36: R
B37: TR3(d) | C37: Transformational research | D37: Expert assessment of progress in embedding sustainable research practices across the institution. | E37: R | F37: R | G37: R | H37: R
B38: CL1(a) | C38: Climate leadership | D38: Annual Greenhouse Gas Inventory (including emissions scopes 1, 2 and 3) demonstrates carbon emission reductions, including maintaining procurement of 100% renewable electricity for all scope 2 sources[1]
B39: CL1(b) | C39: Climate leadership | D39: Development of Greenhouse Gas intensity metrics
B40: CL1(c) | C40: Climate leadership | D40: Review of Climate Leadership targets by 2030.[2] | I40: R
B41: CL2(a) | C41: Climate leadership | D41: By 2028, develop and document institutional mapping of research and education activities that are designed to contribute to global decarbonisation | E41: R | F41: R | G41: R | H41: R | I41: R
B42: CL2(b) | C42: Climate leadership | D42: Prioritised pipeline of decarbonisation focused research and education opportunities aligned with University emissions reduction priorities from 2028
...

Sheet 4. Request tracker
A1: ↑ | B1: End-2026 target status assessment and reporting
B2: 4. Request tracker
B4: Summary
C5: Not sent | E5: Sent | G5: Chased | I5: Support meeting | L5: Response rate | N5: Owner confirmed
C6: =COUNTIF($N$10:$N$20,"Not sent") | E6: =COUNTIF($N$10:$N$20,"Sent") | G6: =COUNTIF($N$10:$N$20,"Chased") | I6: =COUNTIF($N$10:$N$20,"Support meeting") | L6: =IFERROR((COUNTIF($N$10:$N$20,"Received")+COUNTIF($N$10:$N$20,"Under review")+COUNTIF($N$10:$N$20,"Complete"))/(COUNTA($N$10:$N$20)-COUNTIF($N$10:$N$20,"Not required")),0) | N6: =COUNTIF($M$10:$M$20,"Yes")&" / "&COUNTA($C$10:$C$20)
C7: Received | E7: Under review | G7: Complete | I7: Not required
C8: =COUNTIF($N$10:$N$20,"Received") | E8: =COUNTIF($N$10:$N$20,"Under review") | G8: =COUNTIF($N$10:$N$20,"Complete") | I8: =COUNTIF($N$10:$N$20,"Not required")
B9: # | C9: Group | D9: Unit / section | E9: Key contact | F9: No. of indicators requested | G9: Request workbook | H9: Date sent | I9: Due date | J9: Reminder date | K9: Support meeting offered/held | L9: Response received | M9: Owner confirmed | N9: Status | O9: Days overdue | P9: Notes / follow-up
B10: F1 | C10: Faculty | D10: ABP – Faculty of Architecture, Building and Planning | E10: TBC | F10: 20 | G10: ABP - end-2026 sustainability reporting request.xlsx | I10: 46402 | J10: =IF(I10="","",I10-7) | N10: Not sent | O10: =IF(OR(I10="",L10<>""),"",MAX(0,TODAY()-I10))
B11: F2 | C11: Faculty | D11: ARTS – Faculty of Arts | E11: TBC | F11: 20 | G11: ARTS - end-2026 sustainability reporting request.xlsx | I11: 46402 | J11: =IF(I11="","",I11-7) | N11: Not sent | O11: =IF(OR(I11="",L11<>""),"",MAX(0,TODAY()-I11))
B12: F3 | C12: Faculty | D12: FBE – Faculty of Business and Economics | E12: TBC | F12: 20 | G12: FBE - end-2026 sustainability reporting request.xlsx | I12: 46402 | J12: =IF(I12="","",I12-7) | N12: Not sent | O12: =IF(OR(I12="",L12<>""),"",MAX(0,TODAY()-I12))
B13: F4 | C13: Faculty | D13: SCI – Faculty of Science | E13: TBC | F13: 20 | G13: SCI - end-2026 sustainability reporting request.xlsx | I13: 46402 | J13: =IF(I13="","",I13-7) | N13: Not sent | O13: =IF(OR(I13="",L13<>""),"",MAX(0,TODAY()-I13))
B14: C1 | C14: Central | D14: CI&S – Estate Planning & Development (TBC: confirm with Gerard) | E14: TBC | F14: 5 | G14: CIandS - end-2026 sustainability reporting request.xlsx | I14: 46402 | J14: =IF(I14="","",I14-7) | N14: Not sent | O14: =IF(OR(I14="",L14<>""),"",MAX(0,TODAY()-I14))
B15: C2 | C15: Central | D15: CI&S – Sustainability Strategy (incl. CLLAP) | E15: TBC | F15: 17 | G15: CIandS - end-2026 sustainability reporting request.xlsx | I15: 46402 | J15: =IF(I15="","",I15-7) | N15: Not sent | O15: =IF(OR(I15="",L15<>""),"",MAX(0,TODAY()-I15))
B16: C3 | C16: Central | D16: CFOG – Procurement | E16: TBC | F16: 6 | G16: CFOG - end-2026 sustainability reporting request.xlsx | I16: 46402 | J16: =IF(I16="","",I16-7) | N16: Not sent | O16: =IF(OR(I16="",L16<>""),"",MAX(0,TODAY()-I16))
B17: C4 | C17: Central | D17: CFOG – Treasury & Investments | E17: TBC | F17: 1 | G17: CFOG - end-2026 sustainability reporting request.xlsx | I17: 46402 | J17: =IF(I17="","",I17-7) | N17: Not sent | O17: =IF(OR(I17="",L17<>""),"",MAX(0,TODAY()-I17))
B18: C5 | C18: Central | D18: ESG – Campus Operations & Sustainability Delivery | E18: TBC | F18: 7 | G18: ESG - end-2026 sustainability reporting request.xlsx | I18: 46402 | J18: =IF(I18="","",I18-7) | N18: Not sent | O18: =IF(OR(I18="",L18<>""),"",MAX(0,TODAY()-I18))
B19: C6 | C19: Central | D19: CIOG – Responsible AI & digital | E19: TBC | F19: 4 | G19: CIOG - end-2026 sustainability reporting request.xlsx | I19: 46402 | J19: =IF(I19="","",I19-7) | N19: Not sent | O19: =IF(OR(I19="",L19<>""),"",MAX(0,TODAY()-I19))
B20: C7 | C20: Central | D20: MRE – Research (incl. MBI – TBC) | E20: TBC | F20: 2 | G20: MRE - end-2026 sustainability reporting request.xlsx | I20: 46402 | J20: =IF(I20="","",I20-7) | N20: Not sent | O20: =IF(OR(I20="",L20<>""),"",MAX(0,TODAY()-I20))

Sheet Faculties
A1: ↑ | B1: End-2026 target status assessment and reporting
B2: Faculties
B3: Consolidated responses – paste from returned request workbooks (identical column layout). Click [+] above Columns H–K for end-2025 responses.
B5: 1.1 ABP – Faculty of Architecture, Building and Planning
C7: Sustainability 2030 target and indicator | H7: End-2025 reporting (for reference – click [+] above to expand) | L7: End-2026 reporting (PLEASE COMPLETE THIS SECTION)
B8: Ref | C8: Priority area | D8: Sustainability 2030 target | E8: Indicator | F8: 2026 Reporting request | G8: How SST will use this data | H8: Related SR25 ref | I8: End-2025 confirmed status | J8: End-2025 reporting response | K8: Links and supporting information | L8: Confirm end-2026 target status | M8: OPTION 1: Target-level reporting (Column D) | N8: OPTION 2: Indicator level reporting (Column E/F) | O8: Supporting information/comments | P8: Data source and limitations | Q8: Data owner confirms information is accurate | R8: Confirmed by (name, role, date)
L9: (Met or exceeded; partially met; not met; not yet started) | M9: Provide further evidence of target status assessment in the form of: A general update on activities in relation to the overarching target (Column D) | N9: Provide further evidence of target status assessment in the form of: Data and commentary in direct response to the reporting request (Column F) | O9: Provide any additional information to support the target status assessment (e.g. links, images, rationale for selection of target status) | P9: Where did this information come from (system, report, survey, person)? Note any gaps or limitations. | Q9: Select 'Yes' to confirm the information provided is accurate and can be used for reporting | R9: Name, role and date of the person confirming
B10: EE1(a) | C10: Exceptional education | D10: Provide our students with learning experiences that help them build the knowledge, skills and relationships to lead change for sustainable societies. | E10: Evidence of innovative approaches to sustainability teaching and learning | F10: In end-2025 reporting your faculty reported on the related SP2030 target 4a(ii) and rated it 'Partially met' (see Column J – click [+] above Columns H–K). Please build on this rather than repeating it, focusing on what is new in 2026. Please provide one or two examples from 2026 of innovative approaches your faculty has used to embed sustainability in teaching and learning (e.g. new or redesigned subjects, curriculum design, pedagogies, assessment approaches or learning resources). Include links to subject pages or resources where available. A full list of subjects is not required. | G10: We will collate examples of innovative sustainability teaching and learning across faculties to inform the Exceptional education section of the 2026 Sustainability Report, and select one or two for short case studies. | H10: 4a(ii) | I10: Partially met | J10: The Faculty has continued to make substantial and discipline-wide progress in embedding sustainability into the curriculum in ways that extend well beyond baseline requirements, ensuring that students critically engage with both the beneficial and harmful impacts of the built environment on environmental and human systems. A central mechanism for this work in 2025 has been the forward planning and strategic renewal of all Master’s programs across the Faculty, led by Professor Dan Hill under the Designing Futures strategy. This process goes beyond incremental subject updates and instead focuses on holistic program-level reform, explicitly positioning sustainability as a core organising principle rather than an add-on topic. In practice, this has involved structured, discipline-specific workshops bringing together all academic staff within each program to reflect on: - the current state of sustainability integration across subjects, - emerging societal, environmental and industry challenges, - the skills and capabilities graduates will require to respond responsibly and effectively, - how sustainability is communicated, scaffolded and reinforced across the program. A recent example is the Master of Construction Management, where a half-day, facilitated workshop brought together the full academic teaching team to collectively review the program’s direction. Guided by Professor Hill, the session examined course narratives, subject sequencing, learning outcomes and focus areas, with particular attention to how issues such as embodied carbon, circular construction, climate risk, systems thinking and ethical responsibility are integrated throughout the degree. The outcome of this process is a clearer, more coherent approach to sustainability that is embedded across core and specialist subjects, rather than confined to standalone units. Complementing this program-level work, the Faculty has continued the development of two new sustainability-focused subjects—one at undergraduate level and one at graduate level—both designed to foster interdisciplinary, applied engagement with climate and sustainability challenges. Ongoing curriculum mapping across programs further supports this effort by identifying sustainability-rich learning pathways and informing both subject development and student advising. Together, these initiatives demonstrate a deliberate and sustained commitment to embedding sustainability deeply and coherently across the curriculum, ensuring that graduates across all disciplines develop a critical understanding of the environmental and human systems they shape through professional practice.
